Workbook
Name OLE_LINK1: 'Propylene Asia'!$B$2
Name OLE_LINK1: 'Propylene EU and US'!$C$2
Name OLE_LINK2: 'Propylene Asia'!$C$2
Name OLE_LINK2: 'Propylene EU and US'!$D$2
Name OLE_LINK3: 'Propylene EU and US'!$C$14
Name OLE_LINK4: 'Propylene EU and US'!$E$14
Name SM_Europe: 'Propylene EU and US'!$A$11

Sheet Гадская табличка
B3: CONTRACT PRICE
C4: Delivery term | E4: ='Propylene EU and US'!C9 -> Jun | F4: ='Propylene EU and US'!D9 -> May | G4: change
B5: Propylene | C5: FD NW Europe | D5: €/t | E5: ='Propylene EU and US'!C10 -> 1555 | F5: ='Propylene EU and US'!D10 -> 1585 | G5: ='Propylene EU and US'!F10 -> -0.018927445
B6: SPOT PRICES
C7: Delivery term
B8: Feedstock | E8: ='Propylene EU and US'!C12 -> June 4 | F8: ='Propylene EU and US'!D12 -> May 28 | G8: change
B9: Propane | C9: CIF ARA | D9: $/t | E9: ='Propylene EU and US'!OLE_LINK3 -> 618 | F9: ='Propylene EU and US'!D14 -> 585 | G9: ='Propylene EU and US'!F14 -> 0.056410256
B10: Butane | C10: CIF ARA | D10: $/t | E10: ='Propylene EU and US'!C15 -> 655 | F10: ='Propylene EU and US'!D15 -> 658 | G10: ='Propylene EU and US'!F15 -> ≈
B11: Naphtha | C11: CIF ARA | D11: $/t | E11: ='Propylene EU and US'!C16 -> 750 | F11: ='Propylene EU and US'!D16 -> 751.75 | G11: ='Propylene EU and US'!F16 -> ≈
B12: Naphtha | C12: CFR Japan | D12: $/t | E12: ='Propylene Asia'!B31 -> 808 | F12: ='Propylene Asia'!C31 -> 835 | G12: ='Propylene Asia'!E31 -> -0.032335329
B13: Propylene
B14: PGP | C14: CIF NW Europe | D14: €/t | E14: ='Propylene EU and US'!C18 -> 1322 | F14: ='Propylene EU and US'!D18 -> 1420 | G14: ='Propylene EU and US'!F18 -> -0.069014085
B15: PGP | C15: FD NW Europe | D15: €/t | E15: ='Propylene EU and US'!C20 -> 1322 | F15: ='Propylene EU and US'!D20 -> 1427 | G15: ='Propylene EU and US'!F20 -> -0.073580939
B16: CGP | C16: CIF NW Europe | D16: €/t | E16: ='Propylene EU and US'!C19 -> 1283 | F16: ='Propylene EU and US'!D19 -> 1347 | G16: ='Propylene EU and US'!F19 -> -0.047512992
B17: PGP | C17: CFR China | D17: $/t | E17: ='Propylene Asia'!B33 -> 1150 | F17: ='Propylene Asia'!C33 -> 1210 | G17: ='Propylene Asia'!E33 -> -0.049586777
B18: PGP | C18: FOB Korea | D18: $/t | E18: ='Propylene Asia'!B34 -> 1130 | F18: ='Propylene Asia'!C34 -> 1200 | G18: ='Propylene Asia'!E34 -> -0.058333333 | J18: ≈
B19: Downstream
B20: PP homo | C20: FD NW Europe | D20: €/t | E20: ='Propylene EU and US'!C22 -> 1,650—1,900 | F20: ='Propylene EU and US'!D22 -> 1,650—1,900 | G20: ='Propylene EU and US'!F22 -> =
B21: PP block copolymer | C21: FD NW Europe | D21: €/t | E21: ='Propylene EU and US'!C23 -> 1,750—1,950 | F21: ='Propylene EU and US'!D23 -> 1,750—1,950 | G21: ='Propylene EU and US'!F23 -> =
B22: Phenol | C22: FOB Rotterdam | D22: $/t | E22: ='Propylene EU and US'!C24 -> 1406 | F22: ='Propylene EU and US'!D24 -> 1410 | G22: ='Propylene EU and US'!F24 -> ≈
B23: Acetone FOB | C23: FOB Rotterdam | D23: $/t | E23: ='Propylene EU and US'!C25 -> 1373 | F23: ='Propylene EU and US'!D25 -> 1441 | G23: ='Propylene EU and US'!F25 -> -0.047189452
B24: PP homo | C24: CFR China | D24: $/t | E24: ='Propylene Asia'!B36 -> 1,200—1,250 | F24: ='Propylene Asia'!C36 -> 1,210—1,280 | G24: ='Propylene Asia'!E36 -> -0.016064257
B25: PP block copolymer | C25: CFR China | D25: $/t | E25: ='Propylene Asia'!B37 -> 1,220—1,270 | F25: ='Propylene Asia'!C37 -> 1,250—1,300 | G25: ='Propylene Asia'!E37 -> -0.023529412
B26: Phenol CFR China | C26: CFR China | D26: $/t | E26: ='Propylene Asia'!B38 -> 990 | F26: ='Propylene Asia'!C38 -> 1000 | G26: ='Propylene Asia'!E38 -> -0.01
B27: Acetone CFR China | C27: CFR China | D27: $/t | E27: ='Propylene Asia'!B39 -> 910 | F27: ='Propylene Asia'!C39 -> 930 | G27: ='Propylene Asia'!E39 -> -0.021505376
B28: ChemCourier
B29: *estimated
B30: ** - prices as of 24 August
B31: ** - prices for 9 February due to Lunar New Year
B32: *** - prices for 10 February due to Lunar New Year

Sheet Title page
A1: PROPYLENE SPOT PRICES, $/t | F1: ШАБЛОН
A2: CIF NWE* | C2: CFR NE Asia | F2: YYY 77 | G2: YYY = | H2: YYY 77
A3: 1,537 114 | C3: 1,150 60
A4: ='Propylene EU and US'!L18 -> 1322 | C4: ='Propylene Asia'!K33 -> 1150
A5: ='Propylene EU and US'!L18-'Propylene EU and US'!Q18 -> -98 | C5: ='Propylene Asia'!K33-'Propylene Asia'!P33 -> -60 | F5: 834 5
A6: не смотри, это в евро, а нужны доллары | F6: 825 5
A11: PROPYLENE CONTRACT PRICE, €/t | F11: ШАБЛОН
A12: June | B12: FD NWE | C12: May | F12: YYY 77 | G12: 845 = | H12: YYY 77
A13: 1555 | B13:  30 | C13: 1585
A14: ='Propylene EU and US'!L10 -> 1555 | B14: =A14-C14 -> -30 | C14: ='Propylene EU and US'!Q10 -> 1585
A18: ='Propylene EU and US'!L32 -> 0
A20: 988
B22: 757
A24: 1537
A25: =A24-1651 -> -114
A27: =A24-A25 -> 1651

Sheet Propylene EU and US
H1: 2026 | I1: 2026
C2: June 4 | D2: May 28 | E2: change | U2: =ADDRESS(2,MATCH(H$1,Database!$D$1:$XFD$1,0)+3,4,,"Database") -> Database!JT2 | V2: =ADDRESS(2,MATCH(I$1,Database!$D$1:$XFD$1,0)+3,4,,"Database") -> Database!JT2
U3: =ADDRESS(50,MATCH(H$1,Database!$D$1:$XFD$1,1)+3,4,,"Database") -> Database!KR50 | V3: =ADDRESS(50,MATCH(I$1,Database!$D$1:$XFD$1,1)+3,4,,"Database") -> Database!KR50
D5: =HLOOKUP(D9,INDIRECT($V$5):INDIRECT($V$6),2,FALSE) -> 1585 | U5: =ADDRESS(2,MATCH($H$1,calc_MCP!$D$1:$XFD$1,0)+3,4,,"calc_MCP") -> calc_MCP!JA2 | V5: =ADDRESS(2,MATCH(I$1,calc_MCP!$D$1:$XFD$1,0)+3,4,,"calc_MCP") -> calc_MCP!JA2
U6: =ADDRESS(10,MATCH(H$1,calc_MCP!$D$1:$XFD$1,1)+3,4,,"calc_MCP") -> calc_MCP!XEK10 | V6: =ADDRESS(10,MATCH(I$1,calc_MCP!$D$1:$XFD$1,1)+3,4,,"calc_MCP") -> calc_MCP!XEK10
A8: CONTRACT PRICES
C9: Jun | D9: May | F9: change
A10: Propylene FD NWE | B10: €/t | C10: =HLOOKUP(C9,INDIRECT($U$5):INDIRECT($U$6),2,FALSE) -> 1555 | D10: =HLOOKUP(D9,INDIRECT($V$5):INDIRECT($V$6),2,FALSE) -> 1585 | E10: =IF(OR(F10="=",F10="≈",F10="—"),"",IF(F10>0,"",IF(F10<0,"",""))) ->  | F10: =S10 -> -0.018927445 | I10: =IFERROR(FIND("—",SUBSTITUTE(C10,"*","")),0) -> 0 | J10: =IF(I10=0,VALUE(SUBSTITUTE(C10,"*","")),VALUE(LEFT(SUBSTITUTE(C10,"*",""),I10-1))) -> 1555 | K10: =IF(I10=0,VALUE(SUBSTITUTE(C10,"*","")),VALUE(RIGHT(SUBSTITUTE(C10,"*",""),LEN(SUBSTITUTE(C10,"*",""))-I10))) -> 1555 | L10: =AVERAGE(J10:K10) -> 1555 | N10: =IFERROR(FIND("—",SUBSTITUTE(D10,"*","")),0) -> 0 | O10: =IF(N10=0,VALUE(SUBSTITUTE(D10,"*","")),VALUE(LEFT(SUBSTITUTE(D10,"*",""),N10-1))) -> 1585 | P10: =IF(N10=0,VALUE(SUBSTITUTE(D10,"*","")),VALUE(RIGHT(SUBSTITUTE(D10,"*",""),LEN(SUBSTITUTE(D10,"*",""))-N10))) -> 1585 | Q10: =AVERAGE(O10:P10) -> 1585 | S10: =IFERROR(IF(L10/Q10-1=0,"=",IF(OR(AND(L10/Q10-1<0.005,L10/Q10-1>0), AND(L10/Q10-1<0,L10/Q10-1>-0.005)),"≈",L10/Q10-1)),"—") -> -0.018927445
A11: SPOT PRICES
C12: =OLE_LINK1 -> June 4 | D12: =OLE_LINK2 -> May 28 | F12: change
A13: Upstream
A14: Propane CIF ARA | B14: $/t | C14: =HLOOKUP(OLE_LINK1,INDIRECT($U$2):INDIRECT($U$3),11,FALSE) -> 618 | D14: =HLOOKUP(OLE_LINK2,INDIRECT($V$2):INDIRECT($V$3),11,FALSE) -> 585 | E14: =IF(OR(F14="=",F14="≈",F14="—"),"",IF(F14>0,"",IF(F14<0,"",""))) ->  | F14: =S14 -> 0.056410256 | I14: =IFERROR(FIND("—",SUBSTITUTE(C14,"*","")),0) -> 0 | J14: =IF(I14=0,VALUE(SUBSTITUTE(C14,"*","")),VALUE(LEFT(SUBSTITUTE(C14,"*",""),I14-1))) -> 618 | K14: =IF(I14=0,VALUE(SUBSTITUTE(C14,"*","")),VALUE(RIGHT(SUBSTITUTE(C14,"*",""),LEN(SUBSTITUTE(C14,"*",""))-I14))) -> 618 | L14: =AVERAGE(J14:K14) -> 618 | N14: =IFERROR(FIND("—",SUBSTITUTE(D14,"*","")),0) -> 0 | O14: =IF(N14=0,VALUE(SUBSTITUTE(D14,"*","")),VALUE(LEFT(SUBSTITUTE(D14,"*",""),N14-1))) -> 585 | P14: =IF(N14=0,VALUE(SUBSTITUTE(D14,"*","")),VALUE(RIGHT(SUBSTITUTE(D14,"*",""),LEN(SUBSTITUTE(D14,"*",""))-N14))) -> 585 | Q14: =AVERAGE(O14:P14) -> 585 | S14: =IFERROR(IF(L14/Q14-1=0,"=",IF(OR(AND(L14/Q14-1<0.005,L14/Q14-1>0), AND(L14/Q14-1<0,L14/Q14-1>-0.005)),"≈",L14/Q14-1)),"—") -> 0.056410256
A15: Butane CIF ARA | B15: $/t | C15: =HLOOKUP(OLE_LINK1,INDIRECT($U$2):INDIRECT($U$3),12,FALSE) -> 655 | D15: =HLOOKUP(OLE_LINK2,INDIRECT($V$2):INDIRECT($V$3),12,FALSE) -> 658 | E15: =IF(OR(F15="=",F15="≈",F15="—"),"",IF(F15>0,"",IF(F15<0,"",""))) | F15: =S15 -> ≈ | I15: =IFERROR(FIND("—",SUBSTITUTE(C15,"*","")),0) -> 0 | J15: =IF(I15=0,VALUE(SUBSTITUTE(C15,"*","")),VALUE(LEFT(SUBSTITUTE(C15,"*",""),I15-1))) -> 655 | K15: =IF(I15=0,VALUE(SUBSTITUTE(C15,"*","")),VALUE(RIGHT(SUBSTITUTE(C15,"*",""),LEN(SUBSTITUTE(C15,"*",""))-I15))) -> 655 | L15: =AVERAGE(J15:K15) -> 655 | N15: =IFERROR(FIND("—",SUBSTITUTE(D15,"*","")),0) -> 0 | O15: =IF(N15=0,VALUE(SUBSTITUTE(D15,"*","")),VALUE(LEFT(SUBSTITUTE(D15,"*",""),N15-1))) -> 658 | P15: =IF(N15=0,VALUE(SUBSTITUTE(D15,"*","")),VALUE(RIGHT(SUBSTITUTE(D15,"*",""),LEN(SUBSTITUTE(D15,"*",""))-N15))) -> 658 | Q15: =AVERAGE(O15:P15) -> 658 | S15: =IFERROR(IF(L15/Q15-1=0,"=",IF(OR(AND(L15/Q15-1<0.005,L15/Q15-1>0), AND(L15/Q15-1<0,L15/Q15-1>-0.005)),"≈",L15/Q15-1)),"—") -> ≈
A16: Naphtha CIF ARA | B16: $/t | C16: =HLOOKUP(OLE_LINK1,INDIRECT($U$2):INDIRECT($U$3),7,FALSE) -> 750 | D16: =HLOOKUP(OLE_LINK2,INDIRECT($V$2):INDIRECT($V$3),7,FALSE) -> 751.75 | E16: =IF(OR(F16="=",F16="≈",F16="—"),"",IF(F16>0,"",IF(F16<0,"",""))) | F16: =S16 -> ≈ | I16: =IFERROR(FIND("—",SUBSTITUTE(C16,"*","")),0) -> 0 | J16: =IF(I16=0,VALUE(SUBSTITUTE(C16,"*","")),VALUE(LEFT(SUBSTITUTE(C16,"*",""),I16-1))) -> 750 | K16: =IF(I16=0,VALUE(SUBSTITUTE(C16,"*","")),VALUE(RIGHT(SUBSTITUTE(C16,"*",""),LEN(SUBSTITUTE(C16,"*",""))-I16))) -> 750 | L16: =AVERAGE(J16:K16) -> 750 | N16: =IFERROR(FIND("—",SUBSTITUTE(D16,"*","")),0) -> 0 | O16: =IF(N16=0,VALUE(SUBSTITUTE(D16,"*","")),VALUE(LEFT(SUBSTITUTE(D16,"*",""),N16-1))) -> 751.75 | P16: =IF(N16=0,VALUE(SUBSTITUTE(D16,"*","")),VALUE(RIGHT(SUBSTITUTE(D16,"*",""),LEN(SUBSTITUTE(D16,"*",""))-N16))) -> 751.75 | Q16: =AVERAGE(O16:P16) -> 751.75 | S16: =IFERROR(IF(L16/Q16-1=0,"=",IF(OR(AND(L16/Q16-1<0.005,L16/Q16-1>0), AND(L16/Q16-1<0,L16/Q16-1>-0.005)),"≈",L16/Q16-1)),"—") -> ≈
A17: C3
A18: Propylene (PG) CIF NWE | B18: €/t | C18: =HLOOKUP(OLE_LINK1,INDIRECT($U$2):INDIRECT($U$3),6,FALSE) -> 1322 | D18: =HLOOKUP(OLE_LINK2,INDIRECT($V$2):INDIRECT($V$3),6,FALSE) -> 1420 | E18: =IF(OR(F18="=",F18="≈",F18="—"),"",IF(F18>0,"",IF(F18<0,"",""))) ->  | F18: =S18 -> -0.069014085 | I18: =IFERROR(FIND("—",SUBSTITUTE(C18,"*","")),0) -> 0 | J18: =IF(I18=0,VALUE(SUBSTITUTE(C18,"*","")),VALUE(LEFT(SUBSTITUTE(C18,"*",""),I18-1))) -> 1322 | K18: =IF(I18=0,VALUE(SUBSTITUTE(C18,"*","")),VALUE(RIGHT(SUBSTITUTE(C18,"*",""),LEN(SUBSTITUTE(C18,"*",""))-I18))) -> 1322 | L18: =AVERAGE(J18:K18) -> 1322 | N18: =IFERROR(FIND("—",SUBSTITUTE(D18,"*","")),0) -> 0 | O18: =IF(N18=0,VALUE(SUBSTITUTE(D18,"*","")),VALUE(LEFT(SUBSTITUTE(D18,"*",""),N18-1))) -> 1420 | P18: =IF(N18=0,VALUE(SUBSTITUTE(D18,"*","")),VALUE(RIGHT(SUBSTITUTE(D18,"*",""),LEN(SUBSTITUTE(D18,"*",""))-N18))) -> 1420 | Q18: =AVERAGE(O18:P18) -> 1420 | S18: =IFERROR(IF(L18/Q18-1=0,"=",IF(OR(AND(L18/Q18-1<0.005,L18/Q18-1>0), AND(L18/Q18-1<0,L18/Q18-1>-0.005)),"≈",L18/Q18-1)),"—") -> -0.069014085
A19: Propylene (CG) CIF NWE | B19: €/t | C19: =HLOOKUP(OLE_LINK1,INDIRECT($U$2):INDIRECT($U$3),5,FALSE) -> 1283 | D19: =HLOOKUP(OLE_LINK2,INDIRECT($V$2):INDIRECT($V$3),5,FALSE) -> 1347 | E19: =IF(OR(F19="=",F19="≈",F19="—"),"",IF(F19>0,"",IF(F19<0,"",""))) ->  | F19: =S19 -> -0.047512992 | I19: =IFERROR(FIND("—",SUBSTITUTE(C19,"*","")),0) -> 0 | J19: =IF(I19=0,VALUE(SUBSTITUTE(C19,"*","")),VALUE(LEFT(SUBSTITUTE(C19,"*",""),I19-1))) -> 1283 | K19: =IF(I19=0,VALUE(SUBSTITUTE(C19,"*","")),VALUE(RIGHT(SUBSTITUTE(C19,"*",""),LEN(SUBSTITUTE(C19,"*",""))-I19))) -> 1283 | L19: =AVERAGE(J19:K19) -> 1283 | N19: =IFERROR(FIND("—",SUBSTITUTE(D19,"*","")),0) -> 0 | O19: =IF(N19=0,VALUE(SUBSTITUTE(D19,"*","")),VALUE(LEFT(SUBSTITUTE(D19,"*",""),N19-1))) -> 1347 | P19: =IF(N19=0,VALUE(SUBSTITUTE(D19,"*","")),VALUE(RIGHT(SUBSTITUTE(D19,"*",""),LEN(SUBSTITUTE(D19,"*",""))-N19))) -> 1347 | Q19: =AVERAGE(O19:P19) -> 1347 | S19: =IFERROR(IF(L19/Q19-1=0,"=",IF(OR(AND(L19/Q19-1<0.005,L19/Q19-1>0), AND(L19/Q19-1<0,L19/Q19-1>-0.005)),"≈",L19/Q19-1)),"—") -> -0.047512992
A20: Propylene (PG) FD NWE | B20: €/t | C20: =HLOOKUP(OLE_LINK1,INDIRECT($U$2):INDIRECT($U$3),9,FALSE) -> 1322 | D20: =HLOOKUP(OLE_LINK2,INDIRECT($V$2):INDIRECT($V$3),9,FALSE) -> 1427 | E20: =IF(OR(F20="=",F20="≈",F20="—"),"",IF(F20>0,"",IF(F20<0,"",""))) ->  | F20: =S20 -> -0.073580939 | I20: =IFERROR(FIND("—",SUBSTITUTE(C20,"*","")),0) -> 0 | J20: =IF(I20=0,VALUE(SUBSTITUTE(C20,"*","")),VALUE(LEFT(SUBSTITUTE(C20,"*",""),I20-1))) -> 1322 | K20: =IF(I20=0,VALUE(SUBSTITUTE(C20,"*","")),VALUE(RIGHT(SUBSTITUTE(C20,"*",""),LEN(SUBSTITUTE(C20,"*",""))-I20))) -> 1322 | L20: =AVERAGE(J20:K20) -> 1322 | N20: =IFERROR(FIND("—",SUBSTITUTE(D20,"*","")),0) -> 0 | O20: =IF(N20=0,VALUE(SUBSTITUTE(D20,"*","")),VALUE(LEFT(SUBSTITUTE(D20,"*",""),N20-1))) -> 1427 | P20: =IF(N20=0,VALUE(SUBSTITUTE(D20,"*","")),VALUE(RIGHT(SUBSTITUTE(D20,"*",""),LEN(SUBSTITUTE(D20,"*",""))-N20))) -> 1427 | Q20: =AVERAGE(O20:P20) -> 1427 | S20: =IFERROR(IF(L20/Q20-1=0,"=",IF(OR(AND(L20/Q20-1<0.005,L20/Q20-1>0), AND(L20/Q20-1<0,L20/Q20-1>-0.005)),"≈",L20/Q20-1)),"—") -> -0.073580939
A21: Downstream
A22: PP homo FD NWE | B22: €/t | C22: =HLOOKUP(OLE_LINK1,INDIRECT($U$2):INDIRECT($U$3),13,FALSE) -> 1,650—1,900 | D22: =HLOOKUP(OLE_LINK2,INDIRECT($V$2):INDIRECT($V$3),13,FALSE) -> 1,650—1,900 | E22: =IF(OR(F22="=",F22="≈",F22="—"),"",IF(F22>0,"",IF(F22<0,"",""))) | F22: =S22 -> = | I22: =IFERROR(FIND("—",SUBSTITUTE(C22,"*","")),0) -> 6 | J22: =IF(I22=0,VALUE(SUBSTITUTE(C22,"*","")),VALUE(LEFT(SUBSTITUTE(C22,"*",""),I22-1))) -> 1650 | K22: =IF(I22=0,VALUE(SUBSTITUTE(C22,"*","")),VALUE(RIGHT(SUBSTITUTE(C22,"*",""),LEN(SUBSTITUTE(C22,"*",""))-I22))) -> 1900 | L22: =AVERAGE(J22:K22) -> 1775 | N22: =IFERROR(FIND("—",SUBSTITUTE(D22,"*","")),0) -> 6 | O22: =IF(N22=0,VALUE(SUBSTITUTE(D22,"*","")),VALUE(LEFT(SUBSTITUTE(D22,"*",""),N22-1))) -> 1650 | P22: =IF(N22=0,VALUE(SUBSTITUTE(D22,"*","")),VALUE(RIGHT(SUBSTITUTE(D22,"*",""),LEN(SUBSTITUTE(D22,"*",""))-N22))) -> 1900 | Q22: =AVERAGE(O22:P22) -> 1775 | S22: =IFERROR(IF(L22/Q22-1=0,"=",IF(OR(AND(L22/Q22-1<0.005,L22/Q22-1>0), AND(L22/Q22-1<0,L22/Q22-1>-0.005)),"≈",L22/Q22-1)),"—") -> =
A23: PP block copolymer FD NWE | B23: €/t | C23: =HLOOKUP(OLE_LINK1,INDIRECT($U$2):INDIRECT($U$3),14,FALSE) -> 1,750—1,950 | D23: =HLOOKUP(OLE_LINK2,INDIRECT($V$2):INDIRECT($V$3),14,FALSE) -> 1,750—1,950 | E23: =IF(OR(F23="=",F23="≈",F23="—"),"",IF(F23>0,"",IF(F23<0,"",""))) | F23: =S23 -> = | I23: =IFERROR(FIND("—",SUBSTITUTE(C23,"*","")),0) -> 6 | J23: =IF(I23=0,VALUE(SUBSTITUTE(C23,"*","")),VALUE(LEFT(SUBSTITUTE(C23,"*",""),I23-1))) -> 1750 | K23: =IF(I23=0,VALUE(SUBSTITUTE(C23,"*","")),VALUE(RIGHT(SUBSTITUTE(C23,"*",""),LEN(SUBSTITUTE(C23,"*",""))-I23))) -> 1950 | L23: =AVERAGE(J23:K23) -> 1850 | N23: =IFERROR(FIND("—",SUBSTITUTE(D23,"*","")),0) -> 6 | O23: =IF(N23=0,VALUE(SUBSTITUTE(D23,"*","")),VALUE(LEFT(SUBSTITUTE(D23,"*",""),N23-1))) -> 1750 | P23: =IF(N23=0,VALUE(SUBSTITUTE(D23,"*","")),VALUE(RIGHT(SUBSTITUTE(D23,"*",""),LEN(SUBSTITUTE(D23,"*",""))-N23))) -> 1950 | Q23: =AVERAGE(O23:P23) -> 1850 | S23: =IFERROR(IF(L23/Q23-1=0,"=",IF(OR(AND(L23/Q23-1<0.005,L23/Q23-1>0), AND(L23/Q23-1<0,L23/Q23-1>-0.005)),"≈",L23/Q23-1)),"—") -> =
A24: Phenol FOB Rotterdam | B24: $/t | C24: =HLOOKUP(OLE_LINK1,INDIRECT($U$2):INDIRECT($U$3),10,FALSE) -> 1406 | D24: =HLOOKUP(OLE_LINK2,INDIRECT($V$2):INDIRECT($V$3),10,FALSE) -> 1410 | E24: =IF(OR(F24="=",F24="≈",F24="—"),"",IF(F24>0,"",IF(F24<0,"",""))) | F24: =S24 -> ≈ | I24: =IFERROR(FIND("—",SUBSTITUTE(C24,"*","")),0) -> 0 | J24: =IF(I24=0,VALUE(SUBSTITUTE(C24,"*","")),VALUE(LEFT(SUBSTITUTE(C24,"*",""),I24-1))) -> 1406 | K24: =IF(I24=0,VALUE(SUBSTITUTE(C24,"*","")),VALUE(RIGHT(SUBSTITUTE(C24,"*",""),LEN(SUBSTITUTE(C24,"*",""))-I24))) -> 1406 | L24: =AVERAGE(J24:K24) -> 1406 | N24: =IFERROR(FIND("—",SUBSTITUTE(D24,"*","")),0) -> 0 | O24: =IF(N24=0,VALUE(SUBSTITUTE(D24,"*","")),VALUE(LEFT(SUBSTITUTE(D24,"*",""),N24-1))) -> 1410 | P24: =IF(N24=0,VALUE(SUBSTITUTE(D24,"*","")),VALUE(RIGHT(SUBSTITUTE(D24,"*",""),LEN(SUBSTITUTE(D24,"*",""))-N24))) -> 1410 | Q24: =AVERAGE(O24:P24) -> 1410 | S24: =IFERROR(IF(L24/Q24-1=0,"=",IF(OR(AND(L24/Q24-1<0.005,L24/Q24-1>0), AND(L24/Q24-1<0,L24/Q24-1>-0.005)),"≈",L24/Q24-1)),"—") -> ≈
A25: Acetone FOB Rotterdam | B25: $/t | C25: =HLOOKUP(OLE_LINK1,INDIRECT($U$2):INDIRECT($U$3),15,FALSE) -> 1373 | D25: =HLOOKUP(OLE_LINK2,INDIRECT($V$2):INDIRECT($V$3),15,FALSE) -> 1441 | E25: =IF(OR(F25="=",F25="≈",F25="—"),"",IF(F25>0,"",IF(F25<0,"",""))) ->  | F25: =S25 -> -0.047189452 | I25: =IFERROR(FIND("—",SUBSTITUTE(C25,"*","")),0) -> 0 | J25: =IF(I25=0,VALUE(SUBSTITUTE(C25,"*","")),VALUE(LEFT(SUBSTITUTE(C25,"*",""),I25-1))) -> 1373 | K25: =IF(I25=0,VALUE(SUBSTITUTE(C25,"*","")),VALUE(RIGHT(SUBSTITUTE(C25,"*",""),LEN(SUBSTITUTE(C25,"*",""))-I25))) -> 1373 | L25: =AVERAGE(J25:K25) -> 1373 | N25: =IFERROR(FIND("—",SUBSTITUTE(D25,"*","")),0) -> 0 | O25: =IF(N25=0,VALUE(SUBSTITUTE(D25,"*","")),VALUE(LEFT(SUBSTITUTE(D25,"*",""),N25-1))) -> 1441 | P25: =IF(N25=0,VALUE(SUBSTITUTE(D25,"*","")),VALUE(RIGHT(SUBSTITUTE(D25,"*",""),LEN(SUBSTITUTE(D25,"*",""))-N25))) -> 1441 | Q25: =AVERAGE(O25:P25) -> 1441 | S25: =IFERROR(IF(L25/Q25-1=0,"=",IF(OR(AND(L25/Q25-1<0.005,L25/Q25-1>0), AND(L25/Q25-1<0,L25/Q25-1>-0.005)),"≈",L25/Q25-1)),"—") -> -0.047189452
A28: CONTRACT PRICE
C29: Aug | D29: Jul | E29: change
A30: FOB US | B30: ¢/lb | C30: =HLOOKUP(C29,INDIRECT($U$5):INDIRECT($U$6),3,FALSE) -> #N/A | D30: =HLOOKUP(D29,INDIRECT($V$5):INDIRECT($V$6),3,FALSE) -> #N/A | E30: =IF(OR(F30="=",F30="≈",F30="—"),"",IF(F30>0,"",IF(F30<0,"",""))) | F30: =S30 -> — | I30: =IFERROR(FIND("—",SUBSTITUTE(C30,"*","")),0) -> 0 | J30: =IF(I30=0,VALUE(SUBSTITUTE(C30,"*","")),VALUE(LEFT(SUBSTITUTE(C30,"*",""),I30-1))) -> #N/A | K30: =IF(I30=0,VALUE(SUBSTITUTE(C30,"*","")),VALUE(RIGHT(SUBSTITUTE(C30,"*",""),LEN(SUBSTITUTE(C30,"*",""))-I30))) -> #N/A | L30: =AVERAGE(J30:K30) -> #N/A | N30: =IFERROR(FIND("—",SUBSTITUTE(D30,"*","")),0) -> 0 | O30: =IF(N30=0,VALUE(SUBSTITUTE(D30,"*","")),VALUE(LEFT(SUBSTITUTE(D30,"*",""),N30-1))) -> #N/A | P30: =IF(N30=0,VALUE(SUBSTITUTE(D30,"*","")),VALUE(RIGHT(SUBSTITUTE(D30,"*",""),LEN(SUBSTITUTE(D30,"*",""))-N30))) -> #N/A | Q30: =AVERAGE(O30:P30) -> #N/A | S30: =IFERROR(IF(L30/Q30-1=0,"=",IF(OR(AND(L30/Q30-1<0.005,L30/Q30-1>0), AND(L30/Q30-1<0,L30/Q30-1>-0.005)),"≈",L30/Q30-1)),"—") -> —
A31: FOB US | B31: $/t | C31: =HLOOKUP(C29,INDIRECT($U$5):INDIRECT($U$6),4,FALSE) -> #N/A | D31: =HLOOKUP(D29,INDIRECT($V$5):INDIRECT($V$6),4,FALSE) -> #N/A | E31: =IF(OR(F31="=",F31="≈",F31="—"),"",IF(F31>0,"",IF(F31<0,"",""))) | F31: =S31 -> — | I31: =IFERROR(FIND("—",SUBSTITUTE(C31,"*","")),0) -> 0 | J31: =IF(I31=0,VALUE(SUBSTITUTE(C31,"*","")),VALUE(LEFT(SUBSTITUTE(C31,"*",""),I31-1))) -> #N/A | K31: =IF(I31=0,VALUE(SUBSTITUTE(C31,"*","")),VALUE(RIGHT(SUBSTITUTE(C31,"*",""),LEN(SUBSTITUTE(C31,"*",""))-I31))) -> #N/A | L31: =AVERAGE(J31:K31) -> #N/A | N31: =IFERROR(FIND("—",SUBSTITUTE(D31,"*","")),0) -> 0 | O31: =IF(N31=0,VALUE(SUBSTITUTE(D31,"*","")),VALUE(LEFT(SUBSTITUTE(D31,"*",""),N31-1))) -> #N/A | P31: =IF(N31=0,VALUE(SUBSTITUTE(D31,"*","")),VALUE(RIGHT(SUBSTITUTE(D31,"*",""),LEN(SUBSTITUTE(D31,"*",""))-N31))) -> #N/A | Q31: =AVERAGE(O31:P31) -> #N/A | S31: =IFERROR(IF(L31/Q31-1=0,"=",IF(OR(AND(L31/Q31-1<0.005,L31/Q31-1>0), AND(L31/Q31-1<0,L31/Q31-1>-0.005)),"≈",L31/Q31-1)),"—") -> —
A32: SPOT PRICES
C33: ='Propylene Asia'!OLE_LINK1 -> June 4 | D33: ='Propylene Asia'!OLE_LINK2 -> May 28 | E33: change
A34: CIF US Gulf | B34: ¢/lb | C34: =HLOOKUP(C33,INDIRECT($U$2):INDIRECT($U$3),30,FALSE) -> 0 | D34: =HLOOKUP(D$33,INDIRECT($V$2):INDIRECT($V$3),30,FALSE) -> 0 | E34: =IF(OR(F34="=",F34="≈",F34="—"),"",IF(F34>0,"",IF(F34<0,"",""))) | F34: =S34 -> — | I34: =IFERROR(FIND("—",SUBSTITUTE(C34,"*","")),0) -> 0 | J34: =IF(I34=0,VALUE(SUBSTITUTE(C34,"*","")),VALUE(LEFT(SUBSTITUTE(C34,"*",""),I34-1))) -> 0 | K34: =IF(I34=0,VALUE(SUBSTITUTE(C34,"*","")),VALUE(RIGHT(SUBSTITUTE(C34,"*",""),LEN(SUBSTITUTE(C34,"*",""))-I34))) -> 0 | L34: =AVERAGE(J34:K34) -> 0 | N34: =IFERROR(FIND("—",SUBSTITUTE(D34,"*","")),0) -> 0 | O34: =IF(N34=0,VALUE(SUBSTITUTE(D34,"*","")),VALUE(LEFT(SUBSTITUTE(D34,"*",""),N34-1))) -> 0 | P34: =IF(N34=0,VALUE(SUBSTITUTE(D34,"*","")),VALUE(RIGHT(SUBSTITUTE(D34,"*",""),LEN(SUBSTITUTE(D34,"*",""))-N34))) -> 0 | Q34: =AVERAGE(O34:P34) -> 0 | S34: =IFERROR(IF(L34/Q34-1=0,"=",IF(OR(AND(L34/Q34-1<0.005,L34/Q34-1>0), AND(L34/Q34-1<0,L34/Q34-1>-0.005)),"≈",L34/Q34-1)),"—") -> —
A35: CIF US Gulf | B35: $/t | C35: =HLOOKUP(C$33,INDIRECT($U$2):INDIRECT($U$3),31,FALSE) -> 0 | D35: =HLOOKUP(D$33,INDIRECT($V$2):INDIRECT($V$3),31,FALSE) -> 0 | E35: =IF(OR(F35="=",F35="≈",F35="—"),"",IF(F35>0,"",IF(F35<0,"",""))) | F35: =S35 -> — | I35: =IFERROR(FIND("—",SUBSTITUTE(C35,"*","")),0) -> 0 | J35: =IF(I35=0,VALUE(SUBSTITUTE(C35,"*","")),VALUE(LEFT(SUBSTITUTE(C35,"*",""),I35-1))) -> 0 | K35: =IF(I35=0,VALUE(SUBSTITUTE(C35,"*","")),VALUE(RIGHT(SUBSTITUTE(C35,"*",""),LEN(SUBSTITUTE(C35,"*",""))-I35))) -> 0 | L35: =AVERAGE(J35:K35) -> 0 | N35: =IFERROR(FIND("—",SUBSTITUTE(D35,"*","")),0) -> 0 | O35: =IF(N35=0,VALUE(SUBSTITUTE(D35,"*","")),VALUE(LEFT(SUBSTITUTE(D35,"*",""),N35-1))) -> 0 | P35: =IF(N35=0,VALUE(SUBSTITUTE(D35,"*","")),VALUE(RIGHT(SUBSTITUTE(D35,"*",""),LEN(SUBSTITUTE(D35,"*",""))-N35))) -> 0 | Q35: =AVERAGE(O35:P35) -> 0 | S35: =IFERROR(IF(L35/Q35-1=0,"=",IF(OR(AND(L35/Q35-1<0.005,L35/Q35-1>0), AND(L35/Q35-1<0,L35/Q35-1>-0.005)),"≈",L35/Q35-1)),"—") -> —
A36: FOB US Gulf | B36: ¢/lb | C36: =HLOOKUP(C$33,INDIRECT($U$2):INDIRECT($U$3),28,FALSE) -> 0 | D36: =HLOOKUP(D$33,INDIRECT($V$2):INDIRECT($V$3),28,FALSE) -> 0 | E36: =IF(OR(F36="=",F36="≈",F36="—"),"",IF(F36>0,"",IF(F36<0,"",""))) | F36: =S36 -> — | I36: =IFERROR(FIND("—",SUBSTITUTE(C36,"*","")),0) -> 0 | J36: =IF(I36=0,VALUE(SUBSTITUTE(C36,"*","")),VALUE(LEFT(SUBSTITUTE(C36,"*",""),I36-1))) -> 0 | K36: =IF(I36=0,VALUE(SUBSTITUTE(C36,"*","")),VALUE(RIGHT(SUBSTITUTE(C36,"*",""),LEN(SUBSTITUTE(C36,"*",""))-I36))) -> 0 | L36: =AVERAGE(J36:K36) -> 0 | N36: =IFERROR(FIND("—",SUBSTITUTE(D36,"*","")),0) -> 0 | O36: =IF(N36=0,VALUE(SUBSTITUTE(D36,"*","")),VALUE(LEFT(SUBSTITUTE(D36,"*",""),N36-1))) -> 0 | P36: =IF(N36=0,VALUE(SUBSTITUTE(D36,"*","")),VALUE(RIGHT(SUBSTITUTE(D36,"*",""),LEN(SUBSTITUTE(D36,"*",""))-N36))) -> 0 | Q36: =AVERAGE(O36:P36) -> 0 | S36: =IFERROR(IF(L36/Q36-1=0,"=",IF(OR(AND(L36/Q36-1<0.005,L36/Q36-1>0), AND(L36/Q36-1<0,L36/Q36-1>-0.005)),"≈",L36/Q36-1)),"—") -> —
A37: FOB US Gulf | B37: $/t | C37: =HLOOKUP(C$33,INDIRECT($U$2):INDIRECT($U$3),29,FALSE) -> 0 | D37: =HLOOKUP(D$33,INDIRECT($V$2):INDIRECT($V$3),29,FALSE) -> 0 | E37: =IF(OR(F37="=",F37="≈",F37="—"),"",IF(F37>0,"",IF(F37<0,"",""))) | F37: =S37 -> — | I37: =IFERROR(FIND("—",SUBSTITUTE(C37,"*","")),0) -> 0 | J37: =IF(I37=0,VALUE(SUBSTITUTE(C37,"*","")),VALUE(LEFT(SUBSTITUTE(C37,"*",""),I37-1))) -> 0 | K37: =IF(I37=0,VALUE(SUBSTITUTE(C37,"*","")),VALUE(RIGHT(SUBSTITUTE(C37,"*",""),LEN(SUBSTITUTE(C37,"*",""))-I37))) -> 0 | L37: =AVERAGE(J37:K37) -> 0 | N37: =IFERROR(FIND("—",SUBSTITUTE(D37,"*","")),0) -> 0 | O37: =IF(N37=0,VALUE(SUBSTITUTE(D37,"*","")),VALUE(LEFT(SUBSTITUTE(D37,"*",""),N37-1))) -> 0 | P37: =IF(N37=0,VALUE(SUBSTITUTE(D37,"*","")),VALUE(RIGHT(SUBSTITUTE(D37,"*",""),LEN(SUBSTITUTE(D37,"*",""))-N37))) -> 0 | Q37: =AVERAGE(O37:P37) -> 0 | S37: =IFERROR(IF(L37/Q37-1=0,"=",IF(OR(AND(L37/Q37-1<0.005,L37/Q37-1>0), AND(L37/Q37-1<0,L37/Q37-1>-0.005)),"≈",L37/Q37-1)),"—") -> —
A39: SPOT PRICES, $/t
C40: =OLE_LINK1 -> June 4 | D40: =OLE_LINK2 -> May 28 | E40: change
A41: Naphtha CFR Japan
A42: Ethylene CFR NEA
A43: Butadiene CFR NEA
A44: Butadiene CFR NEA (bid/offer)
A45: Butadiene CFR SEA
...

Sheet Propylene Asia
A1: SPOT PRICES, RUB/t inc VAT*
B2: June 4 | C2: May 28 | D2: change | T2: ='Propylene EU and US'!U2 -> Database!JT2 | U2: ='Propylene EU and US'!V2 -> Database!JT2
A3: C3 | T3: ='Propylene EU and US'!U3 -> Database!KR50 | U3: ='Propylene EU and US'!V3 -> Database!KR50
A4: Propylene FCA VFD | B4: =HLOOKUP(OLE_LINK1,INDIRECT($T$2):INDIRECT($T$3),3,FALSE) -> 60,000—65,000 | C4: =HLOOKUP(OLE_LINK2,INDIRECT($U$2):INDIRECT($U$3),3,FALSE) -> 60,000—65,000 | D4: =IF(OR(E4="=",E4="≈",E4="—"),"",IF(E4>0,"",IF(E4<0,"",""))) | E4: =R4 -> = | H4: =IFERROR(FIND("—",SUBSTITUTE(B4,"*","")),0) -> 7 | I4: =IF(H4=0,VALUE(SUBSTITUTE(B4,"*","")),VALUE(LEFT(SUBSTITUTE(B4,"*",""),H4-1))) -> 60000 | J4: =IF(H4=0,VALUE(SUBSTITUTE(B4,"*","")),VALUE(RIGHT(SUBSTITUTE(B4,"*",""),LEN(SUBSTITUTE(B4,"*",""))-H4))) -> 65000 | K4: =AVERAGE(I4:J4) -> 62500 | M4: =IFERROR(FIND("—",SUBSTITUTE(C4,"*","")),0) -> 7 | N4: =IF(M4=0,VALUE(SUBSTITUTE(C4,"*","")),VALUE(LEFT(SUBSTITUTE(C4,"*",""),M4-1))) -> 60000 | O4: =IF(M4=0,VALUE(SUBSTITUTE(C4,"*","")),VALUE(RIGHT(SUBSTITUTE(C4,"*",""),LEN(SUBSTITUTE(C4,"*",""))-M4))) -> 65000 | P4: =AVERAGE(N4:O4) -> 62500 | R4: =IFERROR(IF(K4/P4-1=0,"=",IF(OR(AND(K4/P4-1<0.005,K4/P4-1>0), AND(K4/P4-1<0,K4/P4-1>-0.005)),"≈",K4/P4-1)),"—") -> =
A5: Downstream
A6: PP homo CPT CFD | B6: =HLOOKUP(OLE_LINK1,INDIRECT($T$2):INDIRECT($T$3),33,FALSE) -> — | C6: =HLOOKUP(OLE_LINK2,INDIRECT($U$2):INDIRECT($U$3),33,FALSE) -> — | D6: =IF(OR(E6="=",E6="≈",E6="—"),"",IF(E6>0,"",IF(E6<0,"",""))) | E6: =R6 -> — | H6: =IFERROR(FIND("—",SUBSTITUTE(B6,"*","")),0) -> 1 | I6: =IF(H6=0,VALUE(SUBSTITUTE(B6,"*","")),VALUE(LEFT(SUBSTITUTE(B6,"*",""),H6-1))) -> #VALUE! | J6: =IF(H6=0,VALUE(SUBSTITUTE(B6,"*","")),VALUE(RIGHT(SUBSTITUTE(B6,"*",""),LEN(SUBSTITUTE(B6,"*",""))-H6))) -> #VALUE! | K6: =AVERAGE(I6:J6) -> #VALUE! | M6: =IFERROR(FIND("—",SUBSTITUTE(C6,"*","")),0) -> 1 | N6: =IF(M6=0,VALUE(SUBSTITUTE(C6,"*","")),VALUE(LEFT(SUBSTITUTE(C6,"*",""),M6-1))) -> #VALUE! | O6: =IF(M6=0,VALUE(SUBSTITUTE(C6,"*","")),VALUE(RIGHT(SUBSTITUTE(C6,"*",""),LEN(SUBSTITUTE(C6,"*",""))-M6))) -> #VALUE! | P6: =AVERAGE(N6:O6) -> #VALUE! | R6: =IFERROR(IF(K6/P6-1=0,"=",IF(OR(AND(K6/P6-1<0.005,K6/P6-1>0), AND(K6/P6-1<0,K6/P6-1>-0.005)),"≈",K6/P6-1)),"—") -> —
A7: PP block copolymer CPT CFD | B7: =HLOOKUP(OLE_LINK1,INDIRECT($T$2):INDIRECT($T$3),34,FALSE) -> — | C7: =HLOOKUP(OLE_LINK2,INDIRECT($U$2):INDIRECT($U$3),34,FALSE) -> — | D7: =IF(OR(E7="=",E7="≈",E7="—"),"",IF(E7>0,"",IF(E7<0,"",""))) | E7: =R7 -> — | H7: =IFERROR(FIND("—",SUBSTITUTE(B7,"*","")),0) -> 1 | I7: =IF(H7=0,VALUE(SUBSTITUTE(B7,"*","")),VALUE(LEFT(SUBSTITUTE(B7,"*",""),H7-1))) -> #VALUE! | J7: =IF(H7=0,VALUE(SUBSTITUTE(B7,"*","")),VALUE(RIGHT(SUBSTITUTE(B7,"*",""),LEN(SUBSTITUTE(B7,"*",""))-H7))) -> #VALUE! | K7: =AVERAGE(I7:J7) -> #VALUE! | M7: =IFERROR(FIND("—",SUBSTITUTE(C7,"*","")),0) -> 1 | N7: =IF(M7=0,VALUE(SUBSTITUTE(C7,"*","")),VALUE(LEFT(SUBSTITUTE(C7,"*",""),M7-1))) -> #VALUE! | O7: =IF(M7=0,VALUE(SUBSTITUTE(C7,"*","")),VALUE(RIGHT(SUBSTITUTE(C7,"*",""),LEN(SUBSTITUTE(C7,"*",""))-M7))) -> #VALUE! | P7: =AVERAGE(N7:O7) -> #VALUE! | R7: =IFERROR(IF(K7/P7-1=0,"=",IF(OR(AND(K7/P7-1<0.005,K7/P7-1>0), AND(K7/P7-1<0,K7/P7-1>-0.005)),"≈",K7/P7-1)),"—") -> —
A8: 1-Butanol FCA VFD | B8: =HLOOKUP(OLE_LINK1,INDIRECT($T$2):INDIRECT($T$3),35,FALSE) -> 102000 | C8: =HLOOKUP(OLE_LINK2,INDIRECT($U$2):INDIRECT($U$3),35,FALSE) -> 80,000—101,000 | D8: =IF(OR(E8="=",E8="≈",E8="—"),"",IF(E8>0,"",IF(E8<0,"",""))) ->  | E8: =R8 -> 0.12707182 | H8: =IFERROR(FIND("—",SUBSTITUTE(B8,"*","")),0) -> 0 | I8: =IF(H8=0,VALUE(SUBSTITUTE(B8,"*","")),VALUE(LEFT(SUBSTITUTE(B8,"*",""),H8-1))) -> 102000 | J8: =IF(H8=0,VALUE(SUBSTITUTE(B8,"*","")),VALUE(RIGHT(SUBSTITUTE(B8,"*",""),LEN(SUBSTITUTE(B8,"*",""))-H8))) -> 102000 | K8: =AVERAGE(I8:J8) -> 102000 | M8: =IFERROR(FIND("—",SUBSTITUTE(C8,"*","")),0) -> 7 | N8: =IF(M8=0,VALUE(SUBSTITUTE(C8,"*","")),VALUE(LEFT(SUBSTITUTE(C8,"*",""),M8-1))) -> 80000 | O8: =IF(M8=0,VALUE(SUBSTITUTE(C8,"*","")),VALUE(RIGHT(SUBSTITUTE(C8,"*",""),LEN(SUBSTITUTE(C8,"*",""))-M8))) -> 101000 | P8: =AVERAGE(N8:O8) -> 90500 | R8: =IFERROR(IF(K8/P8-1=0,"=",IF(OR(AND(K8/P8-1<0.005,K8/P8-1>0), AND(K8/P8-1<0,K8/P8-1>-0.005)),"≈",K8/P8-1)),"—") -> 0.12707182
A9: 2-Ethylhexanol FCA VFD | B9: =HLOOKUP(OLE_LINK1,INDIRECT($T$2):INDIRECT($T$3),36,FALSE) -> 145000 | C9: =HLOOKUP(OLE_LINK2,INDIRECT($U$2):INDIRECT($U$3),36,FALSE) -> 160000 | D9: =IF(OR(E9="=",E9="≈",E9="—"),"",IF(E9>0,"",IF(E9<0,"",""))) ->  | E9: =R9 -> -0.09375 | H9: =IFERROR(FIND("—",SUBSTITUTE(B9,"*","")),0) -> 0 | I9: =IF(H9=0,VALUE(SUBSTITUTE(B9,"*","")),VALUE(LEFT(SUBSTITUTE(B9,"*",""),H9-1))) -> 145000 | J9: =IF(H9=0,VALUE(SUBSTITUTE(B9,"*","")),VALUE(RIGHT(SUBSTITUTE(B9,"*",""),LEN(SUBSTITUTE(B9,"*",""))-H9))) -> 145000 | K9: =AVERAGE(I9:J9) -> 145000 | M9: =IFERROR(FIND("—",SUBSTITUTE(C9,"*","")),0) -> 0 | N9: =IF(M9=0,VALUE(SUBSTITUTE(C9,"*","")),VALUE(LEFT(SUBSTITUTE(C9,"*",""),M9-1))) -> 160000 | O9: =IF(M9=0,VALUE(SUBSTITUTE(C9,"*","")),VALUE(RIGHT(SUBSTITUTE(C9,"*",""),LEN(SUBSTITUTE(C9,"*",""))-M9))) -> 160000 | P9: =AVERAGE(N9:O9) -> 160000 | R9: =IFERROR(IF(K9/P9-1=0,"=",IF(OR(AND(K9/P9-1<0.005,K9/P9-1>0), AND(K9/P9-1<0,K9/P9-1>-0.005)),"≈",K9/P9-1)),"—") -> -0.09375
A10: Acrylic acid EXW VFD | B10: =HLOOKUP(OLE_LINK1,INDIRECT($T$2):INDIRECT($T$3),37,FALSE) -> — | C10: =HLOOKUP(OLE_LINK2,INDIRECT($U$2):INDIRECT($U$3),37,FALSE) -> 190000 | D10: =IF(OR(E10="=",E10="≈",E10="—"),"",IF(E10>0,"",IF(E10<0,"",""))) | E10: =R10 -> — | H10: =IFERROR(FIND("—",SUBSTITUTE(B10,"*","")),0) -> 1 | I10: =IF(H10=0,VALUE(SUBSTITUTE(B10,"*","")),VALUE(LEFT(SUBSTITUTE(B10,"*",""),H10-1))) -> #VALUE! | J10: =IF(H10=0,VALUE(SUBSTITUTE(B10,"*","")),VALUE(RIGHT(SUBSTITUTE(B10,"*",""),LEN(SUBSTITUTE(B10,"*",""))-H10))) -> #VALUE! | K10: =AVERAGE(I10:J10) -> #VALUE! | M10: =IFERROR(FIND("—",SUBSTITUTE(C10,"*","")),0) -> 0 | N10: =IF(M10=0,VALUE(SUBSTITUTE(C10,"*","")),VALUE(LEFT(SUBSTITUTE(C10,"*",""),M10-1))) -> 190000 | O10: =IF(M10=0,VALUE(SUBSTITUTE(C10,"*","")),VALUE(RIGHT(SUBSTITUTE(C10,"*",""),LEN(SUBSTITUTE(C10,"*",""))-M10))) -> 190000 | P10: =AVERAGE(N10:O10) -> 190000 | R10: =IFERROR(IF(K10/P10-1=0,"=",IF(OR(AND(K10/P10-1<0.005,K10/P10-1>0), AND(K10/P10-1<0,K10/P10-1>-0.005)),"≈",K10/P10-1)),"—") -> —
A11: Phenol FCA VFD | B11: =HLOOKUP(OLE_LINK1,INDIRECT($T$2):INDIRECT($T$3),38,FALSE) -> 90,000—90,500 | C11: =HLOOKUP(OLE_LINK2,INDIRECT($U$2):INDIRECT($U$3),38,FALSE) -> 87,500—88,000 | D11: =IF(OR(E11="=",E11="≈",E11="—"),"",IF(E11>0,"",IF(E11<0,"",""))) ->  | E11: =R11 -> 0.028490028 | H11: =IFERROR(FIND("—",SUBSTITUTE(B11,"*","")),0) -> 7 | I11: =IF(H11=0,VALUE(SUBSTITUTE(B11,"*","")),VALUE(LEFT(SUBSTITUTE(B11,"*",""),H11-1))) -> 90000 | J11: =IF(H11=0,VALUE(SUBSTITUTE(B11,"*","")),VALUE(RIGHT(SUBSTITUTE(B11,"*",""),LEN(SUBSTITUTE(B11,"*",""))-H11))) -> 90500 | K11: =AVERAGE(I11:J11) -> 90250 | M11: =IFERROR(FIND("—",SUBSTITUTE(C11,"*","")),0) -> 7 | N11: =IF(M11=0,VALUE(SUBSTITUTE(C11,"*","")),VALUE(LEFT(SUBSTITUTE(C11,"*",""),M11-1))) -> 87500 | O11: =IF(M11=0,VALUE(SUBSTITUTE(C11,"*","")),VALUE(RIGHT(SUBSTITUTE(C11,"*",""),LEN(SUBSTITUTE(C11,"*",""))-M11))) -> 88000 | P11: =AVERAGE(N11:O11) -> 87750 | R11: =IFERROR(IF(K11/P11-1=0,"=",IF(OR(AND(K11/P11-1<0.005,K11/P11-1>0), AND(K11/P11-1<0,K11/P11-1>-0.005)),"≈",K11/P11-1)),"—") -> 0.028490028
A12: Acetone FCA VFD | B12: =HLOOKUP(OLE_LINK1,INDIRECT($T$2):INDIRECT($T$3),39,FALSE) -> 73,000—75,000 | C12: =HLOOKUP(OLE_LINK2,INDIRECT($U$2):INDIRECT($U$3),39,FALSE) -> 73,000—75,000 | D12: =IF(OR(E12="=",E12="≈",E12="—"),"",IF(E12>0,"",IF(E12<0,"",""))) | E12: =R12 -> = | H12: =IFERROR(FIND("—",SUBSTITUTE(B12,"*","")),0) -> 7 | I12: =IF(H12=0,VALUE(SUBSTITUTE(B12,"*","")),VALUE(LEFT(SUBSTITUTE(B12,"*",""),H12-1))) -> 73000 | J12: =IF(H12=0,VALUE(SUBSTITUTE(B12,"*","")),VALUE(RIGHT(SUBSTITUTE(B12,"*",""),LEN(SUBSTITUTE(B12,"*",""))-H12))) -> 75000 | K12: =AVERAGE(I12:J12) -> 74000 | M12: =IFERROR(FIND("—",SUBSTITUTE(C12,"*","")),0) -> 7 | N12: =IF(M12=0,VALUE(SUBSTITUTE(C12,"*","")),VALUE(LEFT(SUBSTITUTE(C12,"*",""),M12-1))) -> 73000 | O12: =IF(M12=0,VALUE(SUBSTITUTE(C12,"*","")),VALUE(RIGHT(SUBSTITUTE(C12,"*",""),LEN(SUBSTITUTE(C12,"*",""))-M12))) -> 75000 | P12: =AVERAGE(N12:O12) -> 74000 | R12: =IFERROR(IF(K12/P12-1=0,"=",IF(OR(AND(K12/P12-1<0.005,K12/P12-1>0), AND(K12/P12-1<0,K12/P12-1>-0.005)),"≈",K12/P12-1)),"—") -> =
A13: SPOT PRICES, $/t ex VAT*
A14: C3
A15: Propylene FCA VFD | B15: =IFERROR(IF(I4=J4,TEXT(I4/1.22/B$24,"#,###"),CONCATENATE(TEXT(I4/1.22/B$24,"#,###"),"—",TEXT(J4/1.22/B$24,"#,###"))),"—") -> 671—726 | C15: =IFERROR(IF(N4=O4,TEXT(N4/1.22/C$24,"#,###"),CONCATENATE(TEXT(N4/1.22/C$24,"#,###"),"—",TEXT(O4/1.22/C$24,"#,###"))),"—") -> 694—751 | D15: =IF(OR(E15="=",E15="≈",E15="—"),"",IF(E15>0,"",IF(E15<0,"",""))) ->  | E15: =R15 -> -0.033217993 | H15: =IFERROR(FIND("—",SUBSTITUTE(B15,"*","")),0) -> 4 | I15: =IF(H15=0,VALUE(SUBSTITUTE(B15,"*","")),VALUE(LEFT(SUBSTITUTE(B15,"*",""),H15-1))) -> 671 | J15: =IF(H15=0,VALUE(SUBSTITUTE(B15,"*","")),VALUE(RIGHT(SUBSTITUTE(B15,"*",""),LEN(SUBSTITUTE(B15,"*",""))-H15))) -> 726 | K15: =AVERAGE(I15:J15) -> 698.5 | M15: =IFERROR(FIND("—",SUBSTITUTE(C15,"*","")),0) -> 4 | N15: =IF(M15=0,VALUE(SUBSTITUTE(C15,"*","")),VALUE(LEFT(SUBSTITUTE(C15,"*",""),M15-1))) -> 694 | O15: =IF(M15=0,VALUE(SUBSTITUTE(C15,"*","")),VALUE(RIGHT(SUBSTITUTE(C15,"*",""),LEN(SUBSTITUTE(C15,"*",""))-M15))) -> 751 | P15: =AVERAGE(N15:O15) -> 722.5 | R15: =IFERROR(IF(K15/P15-1=0,"=",IF(OR(AND(K15/P15-1<0.005,K15/P15-1>0), AND(K15/P15-1<0,K15/P15-1>-0.005)),"≈",K15/P15-1)),"—") -> -0.033217993
A16: Downstream
A17: PP homo CPT CFD | B17: =IFERROR(IF(I6=J6,TEXT(I6/1.22/B$24,"#,###"),CONCATENATE(TEXT(I6/1.22/B$24,"#,###"),"—",TEXT(J6/1.22/B$24,"#,###"))),"—") -> — | C17: =IFERROR(IF(N6=O6,TEXT(N6/1.22/C$24,"#,###"),CONCATENATE(TEXT(N6/1.22/C$24,"#,###"),"—",TEXT(O6/1.22/C$24,"#,###"))),"—") -> — | D17: =IF(OR(E17="=",E17="≈",E17="—"),"",IF(E17>0,"",IF(E17<0,"",""))) | E17: =R17 -> — | H17: =IFERROR(FIND("—",SUBSTITUTE(B17,"*","")),0) -> 1 | I17: =IF(H17=0,VALUE(SUBSTITUTE(B17,"*","")),VALUE(LEFT(SUBSTITUTE(B17,"*",""),H17-1))) -> #VALUE! | J17: =IF(H17=0,VALUE(SUBSTITUTE(B17,"*","")),VALUE(RIGHT(SUBSTITUTE(B17,"*",""),LEN(SUBSTITUTE(B17,"*",""))-H17))) -> #VALUE! | K17: =AVERAGE(I17:J17) -> #VALUE! | M17: =IFERROR(FIND("—",SUBSTITUTE(C17,"*","")),0) -> 1 | N17: =IF(M17=0,VALUE(SUBSTITUTE(C17,"*","")),VALUE(LEFT(SUBSTITUTE(C17,"*",""),M17-1))) -> #VALUE! | O17: =IF(M17=0,VALUE(SUBSTITUTE(C17,"*","")),VALUE(RIGHT(SUBSTITUTE(C17,"*",""),LEN(SUBSTITUTE(C17,"*",""))-M17))) -> #VALUE! | P17: =AVERAGE(N17:O17) -> #VALUE! | R17: =IFERROR(IF(K17/P17-1=0,"=",IF(OR(AND(K17/P17-1<0.005,K17/P17-1>0), AND(K17/P17-1<0,K17/P17-1>-0.005)),"≈",K17/P17-1)),"—") -> —
A18: PP block copolymer CPT CFD | B18: =IFERROR(IF(I7=J7,TEXT(I7/1.22/B$24,"#,###"),CONCATENATE(TEXT(I7/1.22/B$24,"#,###"),"—",TEXT(J7/1.22/B$24,"#,###"))),"—") -> — | C18: =IFERROR(IF(N7=O7,TEXT(N7/1.22/C$24,"#,###"),CONCATENATE(TEXT(N7/1.22/C$24,"#,###"),"—",TEXT(O7/1.22/C$24,"#,###"))),"—") -> — | D18: =IF(OR(E18="=",E18="≈",E18="—"),"",IF(E18>0,"",IF(E18<0,"",""))) | E18: =R18 -> — | H18: =IFERROR(FIND("—",SUBSTITUTE(B18,"*","")),0) -> 1 | I18: =IF(H18=0,VALUE(SUBSTITUTE(B18,"*","")),VALUE(LEFT(SUBSTITUTE(B18,"*",""),H18-1))) -> #VALUE! | J18: =IF(H18=0,VALUE(SUBSTITUTE(B18,"*","")),VALUE(RIGHT(SUBSTITUTE(B18,"*",""),LEN(SUBSTITUTE(B18,"*",""))-H18))) -> #VALUE! | K18: =AVERAGE(I18:J18) -> #VALUE! | M18: =IFERROR(FIND("—",SUBSTITUTE(C18,"*","")),0) -> 1 | N18: =IF(M18=0,VALUE(SUBSTITUTE(C18,"*","")),VALUE(LEFT(SUBSTITUTE(C18,"*",""),M18-1))) -> #VALUE! | O18: =IF(M18=0,VALUE(SUBSTITUTE(C18,"*","")),VALUE(RIGHT(SUBSTITUTE(C18,"*",""),LEN(SUBSTITUTE(C18,"*",""))-M18))) -> #VALUE! | P18: =AVERAGE(N18:O18) -> #VALUE! | R18: =IFERROR(IF(K18/P18-1=0,"=",IF(OR(AND(K18/P18-1<0.005,K18/P18-1>0), AND(K18/P18-1<0,K18/P18-1>-0.005)),"≈",K18/P18-1)),"—") -> —
A19: 1-Butanol FCA VFD | B19: =IFERROR(IF(I8=J8,TEXT(I8/1.22/B$24,"#,###"),CONCATENATE(TEXT(I8/1.22/B$24,"#,###"),"—",TEXT(J8/1.22/B$24,"#,###"))),"—") -> 1,140 | C19: =IFERROR(IF(N8=O8,TEXT(N8/1.22/C$24,"#,###"),CONCATENATE(TEXT(N8/1.22/C$24,"#,###"),"—",TEXT(O8/1.22/C$24,"#,###"))),"—") -> 925—1,168 | D19: =IF(OR(E19="=",E19="≈",E19="—"),"",IF(E19>0,"",IF(E19<0,"",""))) ->  | E19: =R19 -> 0.089345437 | H19: =IFERROR(FIND("—",SUBSTITUTE(B19,"*","")),0) -> 0 | I19: =IF(H19=0,VALUE(SUBSTITUTE(B19,"*","")),VALUE(LEFT(SUBSTITUTE(B19,"*",""),H19-1))) -> 1140 | J19: =IF(H19=0,VALUE(SUBSTITUTE(B19,"*","")),VALUE(RIGHT(SUBSTITUTE(B19,"*",""),LEN(SUBSTITUTE(B19,"*",""))-H19))) -> 1140 | K19: =AVERAGE(I19:J19) -> 1140 | M19: =IFERROR(FIND("—",SUBSTITUTE(C19,"*","")),0) -> 4 | N19: =IF(M19=0,VALUE(SUBSTITUTE(C19,"*","")),VALUE(LEFT(SUBSTITUTE(C19,"*",""),M19-1))) -> 925 | O19: =IF(M19=0,VALUE(SUBSTITUTE(C19,"*","")),VALUE(RIGHT(SUBSTITUTE(C19,"*",""),LEN(SUBSTITUTE(C19,"*",""))-M19))) -> 1168 | P19: =AVERAGE(N19:O19) -> 1046.5 | R19: =IFERROR(IF(K19/P19-1=0,"=",IF(OR(AND(K19/P19-1<0.005,K19/P19-1>0), AND(K19/P19-1<0,K19/P19-1>-0.005)),"≈",K19/P19-1)),"—") -> 0.089345437
A20: 2-Ethylhexanol FCA VFD | B20: =IFERROR(IF(I9=J9,TEXT(I9/1.22/B$24,"#,###"),CONCATENATE(TEXT(I9/1.22/B$24,"#,###"),"—",TEXT(J9/1.22/B$24,"#,###"))),"—") -> 1,621 | C20: =IFERROR(IF(N9=O9,TEXT(N9/1.22/C$24,"#,###"),CONCATENATE(TEXT(N9/1.22/C$24,"#,###"),"—",TEXT(O9/1.22/C$24,"#,###"))),"—") -> 1,850 | D20: =IF(OR(E20="=",E20="≈",E20="—"),"",IF(E20>0,"",IF(E20<0,"",""))) ->  | E20: =R20 -> -0.12378378 | H20: =IFERROR(FIND("—",SUBSTITUTE(B20,"*","")),0) -> 0 | I20: =IF(H20=0,VALUE(SUBSTITUTE(B20,"*","")),VALUE(LEFT(SUBSTITUTE(B20,"*",""),H20-1))) -> 1621 | J20: =IF(H20=0,VALUE(SUBSTITUTE(B20,"*","")),VALUE(RIGHT(SUBSTITUTE(B20,"*",""),LEN(SUBSTITUTE(B20,"*",""))-H20))) -> 1621 | K20: =AVERAGE(I20:J20) -> 1621 | M20: =IFERROR(FIND("—",SUBSTITUTE(C20,"*","")),0) -> 0 | N20: =IF(M20=0,VALUE(SUBSTITUTE(C20,"*","")),VALUE(LEFT(SUBSTITUTE(C20,"*",""),M20-1))) -> 1850 | O20: =IF(M20=0,VALUE(SUBSTITUTE(C20,"*","")),VALUE(RIGHT(SUBSTITUTE(C20,"*",""),LEN(SUBSTITUTE(C20,"*",""))-M20))) -> 1850 | P20: =AVERAGE(N20:O20) -> 1850 | R20: =IFERROR(IF(K20/P20-1=0,"=",IF(OR(AND(K20/P20-1<0.005,K20/P20-1>0), AND(K20/P20-1<0,K20/P20-1>-0.005)),"≈",K20/P20-1)),"—") -> -0.12378378
A21: Acrylic acid EXW VFD | B21: =IFERROR(IF(I10=J10,TEXT(I10/1.22/B$24,"#,###"),CONCATENATE(TEXT(I10/1.22/B$24,"#,###"),"—",TEXT(J10/1.22/B$24,"#,###"))),"—") -> — | C21: =IFERROR(IF(N10=O10,TEXT(N10/1.22/C$24,"#,###"),CONCATENATE(TEXT(N10/1.22/C$24,"#,###"),"—",TEXT(O10/1.22/C$24,"#,###"))),"—") -> 2,197 | D21: =IF(OR(E21="=",E21="≈",E21="—"),"",IF(E21>0,"",IF(E21<0,"",""))) | E21: =R21 -> — | H21: =IFERROR(FIND("—",SUBSTITUTE(B21,"*","")),0) -> 1 | I21: =IF(H21=0,VALUE(SUBSTITUTE(B21,"*","")),VALUE(LEFT(SUBSTITUTE(B21,"*",""),H21-1))) -> #VALUE! | J21: =IF(H21=0,VALUE(SUBSTITUTE(B21,"*","")),VALUE(RIGHT(SUBSTITUTE(B21,"*",""),LEN(SUBSTITUTE(B21,"*",""))-H21))) -> #VALUE! | K21: =AVERAGE(I21:J21) -> #VALUE! | M21: =IFERROR(FIND("—",SUBSTITUTE(C21,"*","")),0) -> 0 | N21: =IF(M21=0,VALUE(SUBSTITUTE(C21,"*","")),VALUE(LEFT(SUBSTITUTE(C21,"*",""),M21-1))) -> 2197 | O21: =IF(M21=0,VALUE(SUBSTITUTE(C21,"*","")),VALUE(RIGHT(SUBSTITUTE(C21,"*",""),LEN(SUBSTITUTE(C21,"*",""))-M21))) -> 2197 | P21: =AVERAGE(N21:O21) -> 2197 | R21: =IFERROR(IF(K21/P21-1=0,"=",IF(OR(AND(K21/P21-1<0.005,K21/P21-1>0), AND(K21/P21-1<0,K21/P21-1>-0.005)),"≈",K21/P21-1)),"—") -> —
A22: Phenol FCA VFD | B22: =IFERROR(IF(I11=J11,TEXT(I11/1.22/B$24,"#,###"),CONCATENATE(TEXT(I11/1.22/B$24,"#,###"),"—",TEXT(J11/1.22/B$24,"#,###"))),"—") -> 1,006—1,011 | C22: =IFERROR(IF(N11=O11,TEXT(N11/1.22/C$24,"#,###"),CONCATENATE(TEXT(N11/1.22/C$24,"#,###"),"—",TEXT(O11/1.22/C$24,"#,###"))),"—") -> 1,012—1,017 | D22: =IF(OR(E22="=",E22="≈",E22="—"),"",IF(E22>0,"",IF(E22<0,"",""))) ->  | E22: =R22 -> -0.0059142435 | H22: =IFERROR(FIND("—",SUBSTITUTE(B22,"*","")),0) -> 6 | I22: =IF(H22=0,VALUE(SUBSTITUTE(B22,"*","")),VALUE(LEFT(SUBSTITUTE(B22,"*",""),H22-1))) -> 1006 | J22: =IF(H22=0,VALUE(SUBSTITUTE(B22,"*","")),VALUE(RIGHT(SUBSTITUTE(B22,"*",""),LEN(SUBSTITUTE(B22,"*",""))-H22))) -> 1011 | K22: =AVERAGE(I22:J22) -> 1008.5 | M22: =IFERROR(FIND("—",SUBSTITUTE(C22,"*","")),0) -> 6 | N22: =IF(M22=0,VALUE(SUBSTITUTE(C22,"*","")),VALUE(LEFT(SUBSTITUTE(C22,"*",""),M22-1))) -> 1012 | O22: =IF(M22=0,VALUE(SUBSTITUTE(C22,"*","")),VALUE(RIGHT(SUBSTITUTE(C22,"*",""),LEN(SUBSTITUTE(C22,"*",""))-M22))) -> 1017 | P22: =AVERAGE(N22:O22) -> 1014.5 | R22: =IFERROR(IF(K22/P22-1=0,"=",IF(OR(AND(K22/P22-1<0.005,K22/P22-1>0), AND(K22/P22-1<0,K22/P22-1>-0.005)),"≈",K22/P22-1)),"—") -> -0.0059142435
A23: Acetone FCA VFD | B23: =IFERROR(IF(I12=J12,TEXT(I12/1.22/B$24,"#,###"),CONCATENATE(TEXT(I12/1.22/B$24,"#,###"),"—",TEXT(J12/1.22/B$24,"#,###"))),"—") -> 816—838 | C23: =IFERROR(IF(N12=O12,TEXT(N12/1.22/C$24,"#,###"),CONCATENATE(TEXT(N12/1.22/C$24,"#,###"),"—",TEXT(O12/1.22/C$24,"#,###"))),"—") -> 844—867 | D23: =IF(OR(E23="=",E23="≈",E23="—"),"",IF(E23>0,"",IF(E23<0,"",""))) ->  | E23: =R23 -> -0.033313852 | H23: =IFERROR(FIND("—",SUBSTITUTE(B23,"*","")),0) -> 4 | I23: =IF(H23=0,VALUE(SUBSTITUTE(B23,"*","")),VALUE(LEFT(SUBSTITUTE(B23,"*",""),H23-1))) -> 816 | J23: =IF(H23=0,VALUE(SUBSTITUTE(B23,"*","")),VALUE(RIGHT(SUBSTITUTE(B23,"*",""),LEN(SUBSTITUTE(B23,"*",""))-H23))) -> 838 | K23: =AVERAGE(I23:J23) -> 827 | M23: =IFERROR(FIND("—",SUBSTITUTE(C23,"*","")),0) -> 4 | N23: =IF(M23=0,VALUE(SUBSTITUTE(C23,"*","")),VALUE(LEFT(SUBSTITUTE(C23,"*",""),M23-1))) -> 844 | O23: =IF(M23=0,VALUE(SUBSTITUTE(C23,"*","")),VALUE(RIGHT(SUBSTITUTE(C23,"*",""),LEN(SUBSTITUTE(C23,"*",""))-M23))) -> 867 | P23: =AVERAGE(N23:O23) -> 855.5 | R23: =IFERROR(IF(K23/P23-1=0,"=",IF(OR(AND(K23/P23-1<0.005,K23/P23-1>0), AND(K23/P23-1<0,K23/P23-1>-0.005)),"≈",K23/P23-1)),"—") -> -0.033313852
A24: USD/RUB | B24: =HLOOKUP(OLE_LINK1,INDIRECT($T$2):INDIRECT($T$3),2,FALSE) -> 73.34 | C24: =HLOOKUP(OLE_LINK2,INDIRECT($U$2):INDIRECT($U$3),2,FALSE) -> 70.9 | D24: =IF(OR(E24="=",E24="≈",E24="—"),"",IF(E24>0,"",IF(E24<0,"",""))) ->  | E24: =R24 -> 0.034414669 | H24: =IFERROR(FIND("—",SUBSTITUTE(B24,"*","")),0) -> 0 | I24: =IF(H24=0,VALUE(SUBSTITUTE(B24,"*","")),VALUE(LEFT(SUBSTITUTE(B24,"*",""),H24-1))) -> 73.34 | J24: =IF(H24=0,VALUE(SUBSTITUTE(B24,"*","")),VALUE(RIGHT(SUBSTITUTE(B24,"*",""),LEN(SUBSTITUTE(B24,"*",""))-H24))) -> 73.34 | K24: =AVERAGE(I24:J24) -> 73.34 | M24: =IFERROR(FIND("—",SUBSTITUTE(C24,"*","")),0) -> 0 | N24: =IF(M24=0,VALUE(SUBSTITUTE(C24,"*","")),VALUE(LEFT(SUBSTITUTE(C24,"*",""),M24-1))) -> 70.9 | O24: =IF(M24=0,VALUE(SUBSTITUTE(C24,"*","")),VALUE(RIGHT(SUBSTITUTE(C24,"*",""),LEN(SUBSTITUTE(C24,"*",""))-M24))) -> 70.9 | P24: =AVERAGE(N24:O24) -> 70.9 | R24: =IFERROR(IF(K24/P24-1=0,"=",IF(OR(AND(K24/P24-1<0.005,K24/P24-1>0), AND(K24/P24-1<0,K24/P24-1>-0.005)),"≈",K24/P24-1)),"—") -> 0.034414669
A28: SPOT PRICES, $/t
B29: =OLE_LINK1 -> June 4 | C29: =OLE_LINK2 -> May 28 | D29: change
A30: Upstream
A31: Naphtha CFR Japan | B31: =HLOOKUP(OLE_LINK1,INDIRECT($T$2):INDIRECT($T$3),17,FALSE) -> 808 | C31: =HLOOKUP(OLE_LINK2,INDIRECT($U$2):INDIRECT($U$3),17,FALSE) -> 835 | D31: =IF(OR(E31="=",E31="≈",E31="—"),"",IF(E31>0,"",IF(E31<0,"",""))) ->  | E31: =R31 -> -0.032335329 | H31: =IFERROR(FIND("—",SUBSTITUTE(B31,"*","")),0) -> 0 | I31: =IF(H31=0,VALUE(SUBSTITUTE(B31,"*","")),VALUE(LEFT(SUBSTITUTE(B31,"*",""),H31-1))) -> 808 | J31: =IF(H31=0,VALUE(SUBSTITUTE(B31,"*","")),VALUE(RIGHT(SUBSTITUTE(B31,"*",""),LEN(SUBSTITUTE(B31,"*",""))-H31))) -> 808 | K31: =AVERAGE(I31:J31) -> 808 | M31: =IFERROR(FIND("—",SUBSTITUTE(C31,"*","")),0) -> 0 | N31: =IF(M31=0,VALUE(SUBSTITUTE(C31,"*","")),VALUE(LEFT(SUBSTITUTE(C31,"*",""),M31-1))) -> 835 | O31: =IF(M31=0,VALUE(SUBSTITUTE(C31,"*","")),VALUE(RIGHT(SUBSTITUTE(C31,"*",""),LEN(SUBSTITUTE(C31,"*",""))-M31))) -> 835 | P31: =AVERAGE(N31:O31) -> 835 | R31: =IFERROR(IF(K31/P31-1=0,"=",IF(OR(AND(K31/P31-1<0.005,K31/P31-1>0), AND(K31/P31-1<0,K31/P31-1>-0.005)),"≈",K31/P31-1)),"—") -> -0.032335329
A32: C3
A33: Propylene (PG) CFR China | B33: =HLOOKUP(OLE_LINK1,INDIRECT($T$2):INDIRECT($T$3),18,FALSE) -> 1150 | C33: =HLOOKUP(OLE_LINK2,INDIRECT($U$2):INDIRECT($U$3),18,FALSE) -> 1210 | D33: =IF(OR(E33="=",E33="≈",E33="—"),"",IF(E33>0,"",IF(E33<0,"",""))) ->  | E33: =R33 -> -0.049586777 | H33: =IFERROR(FIND("—",SUBSTITUTE(B33,"*","")),0) -> 0 | I33: =IF(H33=0,VALUE(SUBSTITUTE(B33,"*","")),VALUE(LEFT(SUBSTITUTE(B33,"*",""),H33-1))) -> 1150 | J33: =IF(H33=0,VALUE(SUBSTITUTE(B33,"*","")),VALUE(RIGHT(SUBSTITUTE(B33,"*",""),LEN(SUBSTITUTE(B33,"*",""))-H33))) -> 1150 | K33: =AVERAGE(I33:J33) -> 1150 | M33: =IFERROR(FIND("—",SUBSTITUTE(C33,"*","")),0) -> 0 | N33: =IF(M33=0,VALUE(SUBSTITUTE(C33,"*","")),VALUE(LEFT(SUBSTITUTE(C33,"*",""),M33-1))) -> 1210 | O33: =IF(M33=0,VALUE(SUBSTITUTE(C33,"*","")),VALUE(RIGHT(SUBSTITUTE(C33,"*",""),LEN(SUBSTITUTE(C33,"*",""))-M33))) -> 1210 | P33: =AVERAGE(N33:O33) -> 1210 | R33: =IFERROR(IF(K33/P33-1=0,"=",IF(OR(AND(K33/P33-1<0.005,K33/P33-1>0), AND(K33/P33-1<0,K33/P33-1>-0.005)),"≈",K33/P33-1)),"—") -> -0.049586777
A34: Propylene (PG) FOB Korea | B34: =HLOOKUP(OLE_LINK1,INDIRECT($T$2):INDIRECT($T$3),19,FALSE) -> 1130 | C34: =HLOOKUP(OLE_LINK2,INDIRECT($U$2):INDIRECT($U$3),19,FALSE) -> 1200 | D34: =IF(OR(E34="=",E34="≈",E34="—"),"",IF(E34>0,"",IF(E34<0,"",""))) ->  | E34: =R34 -> -0.058333333 | H34: =IFERROR(FIND("—",SUBSTITUTE(B34,"*","")),0) -> 0 | I34: =IF(H34=0,VALUE(SUBSTITUTE(B34,"*","")),VALUE(LEFT(SUBSTITUTE(B34,"*",""),H34-1))) -> 1130 | J34: =IF(H34=0,VALUE(SUBSTITUTE(B34,"*","")),VALUE(RIGHT(SUBSTITUTE(B34,"*",""),LEN(SUBSTITUTE(B34,"*",""))-H34))) -> 1130 | K34: =AVERAGE(I34:J34) -> 1130 | M34: =IFERROR(FIND("—",SUBSTITUTE(C34,"*","")),0) -> 0 | N34: =IF(M34=0,VALUE(SUBSTITUTE(C34,"*","")),VALUE(LEFT(SUBSTITUTE(C34,"*",""),M34-1))) -> 1200 | O34: =IF(M34=0,VALUE(SUBSTITUTE(C34,"*","")),VALUE(RIGHT(SUBSTITUTE(C34,"*",""),LEN(SUBSTITUTE(C34,"*",""))-M34))) -> 1200 | P34: =AVERAGE(N34:O34) -> 1200 | R34: =IFERROR(IF(K34/P34-1=0,"=",IF(OR(AND(K34/P34-1<0.005,K34/P34-1>0), AND(K34/P34-1<0,K34/P34-1>-0.005)),"≈",K34/P34-1)),"—") -> -0.058333333
A35: Downstream
A36: PP homo CFR China | B36: =HLOOKUP(OLE_LINK1,INDIRECT($T$2):INDIRECT($T$3),20,FALSE) -> 1,200—1,250 | C36: =HLOOKUP(OLE_LINK2,INDIRECT($U$2):INDIRECT($U$3),20,FALSE) -> 1,210—1,280 | D36: =IF(OR(E36="=",E36="≈",E36="—"),"",IF(E36>0,"",IF(E36<0,"",""))) ->  | E36: =R36 -> -0.016064257 | H36: =IFERROR(FIND("—",SUBSTITUTE(B36,"*","")),0) -> 6 | I36: =IF(H36=0,VALUE(SUBSTITUTE(B36,"*","")),VALUE(LEFT(SUBSTITUTE(B36,"*",""),H36-1))) -> 1200 | J36: =IF(H36=0,VALUE(SUBSTITUTE(B36,"*","")),VALUE(RIGHT(SUBSTITUTE(B36,"*",""),LEN(SUBSTITUTE(B36,"*",""))-H36))) -> 1250 | K36: =AVERAGE(I36:J36) -> 1225 | M36: =IFERROR(FIND("—",SUBSTITUTE(C36,"*","")),0) -> 6 | N36: =IF(M36=0,VALUE(SUBSTITUTE(C36,"*","")),VALUE(LEFT(SUBSTITUTE(C36,"*",""),M36-1))) -> 1210 | O36: =IF(M36=0,VALUE(SUBSTITUTE(C36,"*","")),VALUE(RIGHT(SUBSTITUTE(C36,"*",""),LEN(SUBSTITUTE(C36,"*",""))-M36))) -> 1280 | P36: =AVERAGE(N36:O36) -> 1245 | R36: =IFERROR(IF(K36/P36-1=0,"=",IF(OR(AND(K36/P36-1<0.005,K36/P36-1>0), AND(K36/P36-1<0,K36/P36-1>-0.005)),"≈",K36/P36-1)),"—") -> -0.016064257
A37: PP block copolymer CFR China | B37: =HLOOKUP(OLE_LINK1,INDIRECT($T$2):INDIRECT($T$3),21,FALSE) -> 1,220—1,270 | C37: =HLOOKUP(OLE_LINK2,INDIRECT($U$2):INDIRECT($U$3),21,FALSE) -> 1,250—1,300 | D37: =IF(OR(E37="=",E37="≈",E37="—"),"",IF(E37>0,"",IF(E37<0,"",""))) ->  | E37: =R37 -> -0.023529412 | H37: =IFERROR(FIND("—",SUBSTITUTE(B37,"*","")),0) -> 6 | I37: =IF(H37=0,VALUE(SUBSTITUTE(B37,"*","")),VALUE(LEFT(SUBSTITUTE(B37,"*",""),H37-1))) -> 1220 | J37: =IF(H37=0,VALUE(SUBSTITUTE(B37,"*","")),VALUE(RIGHT(SUBSTITUTE(B37,"*",""),LEN(SUBSTITUTE(B37,"*",""))-H37))) -> 1270 | K37: =AVERAGE(I37:J37) -> 1245 | M37: =IFERROR(FIND("—",SUBSTITUTE(C37,"*","")),0) -> 6 | N37: =IF(M37=0,VALUE(SUBSTITUTE(C37,"*","")),VALUE(LEFT(SUBSTITUTE(C37,"*",""),M37-1))) -> 1250 | O37: =IF(M37=0,VALUE(SUBSTITUTE(C37,"*","")),VALUE(RIGHT(SUBSTITUTE(C37,"*",""),LEN(SUBSTITUTE(C37,"*",""))-M37))) -> 1300 | P37: =AVERAGE(N37:O37) -> 1275 | R37: =IFERROR(IF(K37/P37-1=0,"=",IF(OR(AND(K37/P37-1<0.005,K37/P37-1>0), AND(K37/P37-1<0,K37/P37-1>-0.005)),"≈",K37/P37-1)),"—") -> -0.023529412
A38: Phenol CFR China | B38: =HLOOKUP(OLE_LINK1,INDIRECT($T$2):INDIRECT($T$3),22,FALSE) -> 990 | C38: =HLOOKUP(OLE_LINK2,INDIRECT($U$2):INDIRECT($U$3),22,FALSE) -> 1000 | D38: =IF(OR(E38="=",E38="≈",E38="—"),"",IF(E38>0,"",IF(E38<0,"",""))) ->  | E38: =R38 -> -0.01 | H38: =IFERROR(FIND("—",SUBSTITUTE(B38,"*","")),0) -> 0 | I38: =IF(H38=0,VALUE(SUBSTITUTE(B38,"*","")),VALUE(LEFT(SUBSTITUTE(B38,"*",""),H38-1))) -> 990 | J38: =IF(H38=0,VALUE(SUBSTITUTE(B38,"*","")),VALUE(RIGHT(SUBSTITUTE(B38,"*",""),LEN(SUBSTITUTE(B38,"*",""))-H38))) -> 990 | K38: =AVERAGE(I38:J38) -> 990 | M38: =IFERROR(FIND("—",SUBSTITUTE(C38,"*","")),0) -> 0 | N38: =IF(M38=0,VALUE(SUBSTITUTE(C38,"*","")),VALUE(LEFT(SUBSTITUTE(C38,"*",""),M38-1))) -> 1000 | O38: =IF(M38=0,VALUE(SUBSTITUTE(C38,"*","")),VALUE(RIGHT(SUBSTITUTE(C38,"*",""),LEN(SUBSTITUTE(C38,"*",""))-M38))) -> 1000 | P38: =AVERAGE(N38:O38) -> 1000 | R38: =IFERROR(IF(K38/P38-1=0,"=",IF(OR(AND(K38/P38-1<0.005,K38/P38-1>0), AND(K38/P38-1<0,K38/P38-1>-0.005)),"≈",K38/P38-1)),"—") -> -0.01
A39: Acetone CFR China | B39: =HLOOKUP(OLE_LINK1,INDIRECT($T$2):INDIRECT($T$3),23,FALSE) -> 910 | C39: =HLOOKUP(OLE_LINK2,INDIRECT($U$2):INDIRECT($U$3),23,FALSE) -> 930 | D39: =IF(OR(E39="=",E39="≈",E39="—"),"",IF(E39>0,"",IF(E39<0,"",""))) ->  | E39: =R39 -> -0.021505376 | H39: =IFERROR(FIND("—",SUBSTITUTE(B39,"*","")),0) -> 0 | I39: =IF(H39=0,VALUE(SUBSTITUTE(B39,"*","")),VALUE(LEFT(SUBSTITUTE(B39,"*",""),H39-1))) -> 910 | J39: =IF(H39=0,VALUE(SUBSTITUTE(B39,"*","")),VALUE(RIGHT(SUBSTITUTE(B39,"*",""),LEN(SUBSTITUTE(B39,"*",""))-H39))) -> 910 | K39: =AVERAGE(I39:J39) -> 910 | M39: =IFERROR(FIND("—",SUBSTITUTE(C39,"*","")),0) -> 0 | N39: =IF(M39=0,VALUE(SUBSTITUTE(C39,"*","")),VALUE(LEFT(SUBSTITUTE(C39,"*",""),M39-1))) -> 930 | O39: =IF(M39=0,VALUE(SUBSTITUTE(C39,"*","")),VALUE(RIGHT(SUBSTITUTE(C39,"*",""),LEN(SUBSTITUTE(C39,"*",""))-M39))) -> 930 | P39: =AVERAGE(N39:O39) -> 930 | R39: =IFERROR(IF(K39/P39-1=0,"=",IF(OR(AND(K39/P39-1<0.005,K39/P39-1>0), AND(K39/P39-1<0,K39/P39-1>-0.005)),"≈",K39/P39-1)),"—") -> -0.021505376
A40: BD quotes in China, CNY/t
B41: =OLE_LINK1 -> June 4 | C41: =OLE_LINK2 -> May 28 | D41: change
A42: EXW East China | B42: =HLOOKUP(OLE_LINK1,INDIRECT($T$2):INDIRECT($T$3),22,FALSE) -> 990 | C42: =HLOOKUP(OLE_LINK2,INDIRECT($U$2):INDIRECT($U$3),22,FALSE) -> 1000 | D42: =IF(OR(E42="=",E42="≈",E42="—"),"",IF(E42>0,"",IF(E42<0,"",""))) ->  | E42: =R42 -> -0.01 | H42: =IFERROR(FIND("—",SUBSTITUTE(B42,"*","")),0) -> 0 | I42: =IF(H42=0,VALUE(SUBSTITUTE(B42,"*","")),VALUE(LEFT(SUBSTITUTE(B42,"*",""),H42-1))) -> 990 | J42: =IF(H42=0,VALUE(SUBSTITUTE(B42,"*","")),VALUE(RIGHT(SUBSTITUTE(B42,"*",""),LEN(SUBSTITUTE(B42,"*",""))-H42))) -> 990 | K42: =AVERAGE(I42:J42) -> 990 | M42: =IFERROR(FIND("—",SUBSTITUTE(C42,"*","")),0) -> 0 | N42: =IF(M42=0,VALUE(SUBSTITUTE(C42,"*","")),VALUE(LEFT(SUBSTITUTE(C42,"*",""),M42-1))) -> 1000 | O42: =IF(M42=0,VALUE(SUBSTITUTE(C42,"*","")),VALUE(RIGHT(SUBSTITUTE(C42,"*",""),LEN(SUBSTITUTE(C42,"*",""))-M42))) -> 1000 | P42: =AVERAGE(N42:O42) -> 1000 | R42: =IFERROR(IF(K42/P42-1=0,"=",IF(OR(AND(K42/P42-1<0.005,K42/P42-1>0), AND(K42/P42-1<0,K42/P42-1>-0.005)),"≈",K42/P42-1)),"—") -> -0.01
A43: EXW North China | B43: =HLOOKUP(OLE_LINK1,INDIRECT($T$2):INDIRECT($T$3),23,FALSE) -> 910 | C43: =HLOOKUP(OLE_LINK2,INDIRECT($U$2):INDIRECT($U$3),23,FALSE) -> 930 | D43: =IF(OR(E43="=",E43="≈",E43="—"),"",IF(E43>0,"",IF(E43<0,"",""))) ->  | E43: =R43 -> -0.021505376 | H43: =IFERROR(FIND("—",SUBSTITUTE(B43,"*","")),0) -> 0 | I43: =IF(H43=0,VALUE(SUBSTITUTE(B43,"*","")),VALUE(LEFT(SUBSTITUTE(B43,"*",""),H43-1))) -> 910 | J43: =IF(H43=0,VALUE(SUBSTITUTE(B43,"*","")),VALUE(RIGHT(SUBSTITUTE(B43,"*",""),LEN(SUBSTITUTE(B43,"*",""))-H43))) -> 910 | K43: =AVERAGE(I43:J43) -> 910 | M43: =IFERROR(FIND("—",SUBSTITUTE(C43,"*","")),0) -> 0 | N43: =IF(M43=0,VALUE(SUBSTITUTE(C43,"*","")),VALUE(LEFT(SUBSTITUTE(C43,"*",""),M43-1))) -> 930 | O43: =IF(M43=0,VALUE(SUBSTITUTE(C43,"*","")),VALUE(RIGHT(SUBSTITUTE(C43,"*",""),LEN(SUBSTITUTE(C43,"*",""))-M43))) -> 930 | P43: =AVERAGE(N43:O43) -> 930 | R43: =IFERROR(IF(K43/P43-1=0,"=",IF(OR(AND(K43/P43-1<0.005,K43/P43-1>0), AND(K43/P43-1<0,K43/P43-1>-0.005)),"≈",K43/P43-1)),"—") -> -0.021505376
...

Sheet Charts
AB21: =IF(LEFT(calc_Charts!AA11,4)=LEFT(calc_Charts!AB11,4),"",LEFT(calc_Charts!AB11,4)) -> 0
C22: =calc_Charts!C10 -> 2026 | D22: =IF(calc_Charts!D10>calc_Charts!C10,calc_Charts!D10,"") | E22: =IF(calc_Charts!E10>calc_Charts!D10,calc_Charts!E10,"") | F22: =IF(calc_Charts!F10>calc_Charts!E10,calc_Charts!F10,"") | G22: =IF(calc_Charts!G10>calc_Charts!F10,calc_Charts!G10,"") | H22: =IF(calc_Charts!H10>calc_Charts!G10,calc_Charts!H10,"") | I22: =IF(calc_Charts!I10>calc_Charts!H10,calc_Charts!I10,"") | J22: =IF(calc_Charts!J10>calc_Charts!I10,calc_Charts!J10,"") | K22: =IF(calc_Charts!K10>calc_Charts!J10,calc_Charts!K10,"") | ... AA22: =IF(calc_Charts!AA10>calc_Charts!Z10,calc_Charts!AA10,"")
C23: =LEFT(calc_Charts!C11,4) -> Jan | D23: =IF(LEFT(calc_Charts!C11,4)=LEFT(calc_Charts!D11,4),"",LEFT(calc_Charts!D11,4)) | E23: =IF(LEFT(calc_Charts!D11,4)=LEFT(calc_Charts!E11,4),"",LEFT(calc_Charts!E11,4)) | F23: =IF(LEFT(calc_Charts!E11,4)=LEFT(calc_Charts!F11,4),"",LEFT(calc_Charts!F11,4)) | G23: =IF(LEFT(calc_Charts!F11,4)=LEFT(calc_Charts!G11,4),"",LEFT(calc_Charts!G11,4)) -> Feb | H23: =IF(LEFT(calc_Charts!G11,4)=LEFT(calc_Charts!H11,4),"",LEFT(calc_Charts!H11,4)) | I23: =IF(LEFT(calc_Charts!H11,4)=LEFT(calc_Charts!I11,4),"",LEFT(calc_Charts!I11,4)) | J23: =IF(LEFT(calc_Charts!I11,4)=LEFT(calc_Charts!J11,4),"",LEFT(calc_Charts!J11,4)) | K23: =IF(LEFT(calc_Charts!J11,4)=LEFT(calc_Charts!K11,4),"",LEFT(calc_Charts!K11,4)) -> Mar | ... AA23: =IF(LEFT(calc_Charts!Z11,4)=LEFT(calc_Charts!AA11,4),"",LEFT(calc_Charts!AA11,4))
B25: Naphtha-Propane | C25: =calc_Charts!C20-calc_Charts!C25 -> 0 | D25: =calc_Charts!D20-calc_Charts!D25 -> 48 | E25: =calc_Charts!E20-calc_Charts!E25 -> 34 | F25: =calc_Charts!F20-calc_Charts!F25 -> 39 | G25: =calc_Charts!G20-calc_Charts!G25 -> 37 | H25: =calc_Charts!H20-calc_Charts!H25 -> 22 | I25: =calc_Charts!I20-calc_Charts!I25 -> 47 | J25: =calc_Charts!J20-calc_Charts!J25 -> 24 | ... AA25: =calc_Charts!AA20-calc_Charts!AA25 -> #N/A
B26: Naphtha-Butane | C26: =calc_Charts!C20-calc_Charts!C30 -> 40 | D26: =calc_Charts!D20-calc_Charts!D30 -> 30 | E26: =calc_Charts!E20-calc_Charts!E30 -> 40 | F26: =calc_Charts!F20-calc_Charts!F30 -> 44 | G26: =calc_Charts!G20-calc_Charts!G30 -> 47 | H26: =calc_Charts!H20-calc_Charts!H30 -> 48 | I26: =calc_Charts!I20-calc_Charts!I30 -> 73 | J26: =calc_Charts!J20-calc_Charts!J30 -> 68 | ... AA26: =calc_Charts!AA20-calc_Charts!AA30 -> #N/A
C28: =calc_MCP!D8 -> 2025 | D28: =IF(calc_MCP!E8>calc_MCP!D8,calc_MCP!E8,"") | E28: =IF(calc_MCP!F8>calc_MCP!E8,calc_MCP!F8,"") | F28: =IF(calc_MCP!G8>calc_MCP!F8,calc_MCP!G8,"") | G28: =IF(calc_MCP!H8>calc_MCP!G8,calc_MCP!H8,"") | H28: =IF(calc_MCP!I8>calc_MCP!H8,calc_MCP!I8,"") | I28: =IF(calc_MCP!J8>calc_MCP!I8,calc_MCP!J8,"") | J28: =IF(calc_MCP!K8>calc_MCP!J8,calc_MCP!K8,"") -> 2026 | K28: =IF(calc_MCP!L8>calc_MCP!K8,calc_MCP!L8,"") | ... O28: =IF(calc_MCP!P8>calc_MCP!O8,calc_MCP!P8,"")
C29: =calc_MCP!D9 -> June | E29: =calc_MCP!F9 -> Aug | G29: =calc_MCP!H9 -> Oct | I29: =calc_MCP!J9 -> Dec | K29: =calc_MCP!L9 -> Feb | M29: =calc_MCP!N9 -> Apr | O29: =calc_MCP!P9 -> June
B30: BD contract USA | C30: =calc_MCP!D14 -> 1015 | D30: =calc_MCP!E14 -> 1015 | E30: =calc_MCP!F14 -> 1005 | F30: =calc_MCP!G14 -> 1005 | G30: =calc_MCP!H14 -> 1005 | H30: =calc_MCP!I14 -> 980 | I30: =calc_MCP!J14 -> 980 | J30: =calc_MCP!K14 -> 950 | ... O30: =calc_MCP!P14 -> 1555
B32: С3 CIF NWE* | C32: =calc_Charts!C39 -> 779.06977 | D32: =calc_Charts!D39 -> 810.46512 | E32: =calc_Charts!E39 -> 819.76744 | F32: =calc_Charts!F39 -> 873.80952 | G32: =calc_Charts!G39 -> 864.70588 | H32: =calc_Charts!H39 -> 895.2381 | I32: =calc_Charts!I39 -> 915.29412 | J32: =calc_Charts!J39 -> 988.23529 | ... AB32: =calc_Charts!AB39 -> #N/A | AC32: это в долларах
B33: C3 CFR China | C33: =calc_Charts!C44 -> 745 | D33: =calc_Charts!D44 -> 770 | E33: =calc_Charts!E44 -> 785 | F33: =calc_Charts!F44 -> 820 | G33: =calc_Charts!G44 -> 825 | H33: =calc_Charts!H44 -> 825 | I33: =calc_Charts!I44 -> 825 | J33: =calc_Charts!J44 -> 840 | ... AB33: =calc_Charts!AB44 -> #N/A
B34: C3 FD US Gulf | C34: =calc_Charts!C71 -> #N/A | D34: =calc_Charts!D71 -> #N/A | E34: =calc_Charts!E71 -> #N/A | F34: =calc_Charts!F71 -> #N/A | G34: =calc_Charts!G71 -> #N/A | H34: =calc_Charts!H71 -> #N/A | I34: =calc_Charts!I71 -> #N/A | J34: =calc_Charts!J71 -> #N/A | ... AA34: =calc_Charts!AA71 -> #N/A
B37: PP homo CFR China | C37: =calc_Charts!C55 -> 767.5 | D37: =calc_Charts!D55 -> 765 | E37: =calc_Charts!E55 -> 767.5 | F37: =calc_Charts!F55 -> 760 | G37: =calc_Charts!G55 -> 765 | H37: =calc_Charts!H55 -> 765 | I37: =calc_Charts!I55 -> 795 | J37: =calc_Charts!J55 -> 795 | ... AB37: =calc_Charts!AB55 -> #N/A
B38: C3 CFR China | C38: =calc_Charts!C44 -> 745 | D38: =calc_Charts!D44 -> 770 | E38: =calc_Charts!E44 -> 785 | F38: =calc_Charts!F44 -> 820 | G38: =calc_Charts!G44 -> 825 | H38: =calc_Charts!H44 -> 825 | I38: =calc_Charts!I44 -> 825 | J38: =calc_Charts!J44 -> 840 | ... AB38: =calc_Charts!AB44 -> #N/A
B39: Naphtha CFR Japan | C39: =calc_Charts!C61 -> 534 | D39: =calc_Charts!D61 -> 560 | E39: =calc_Charts!E61 -> 559 | F39: =calc_Charts!F61 -> 585 | G39: =calc_Charts!G61 -> 598 | H39: =calc_Charts!H61 -> 612 | I39: =calc_Charts!I61 -> 594 | J39: =calc_Charts!J61 -> 616 | ... AB39: =calc_Charts!AB61 -> #N/A
B42: Naphtha CIF ARA | C42: =calc_Charts!C20 -> 489 | D42: =calc_Charts!D20 -> 536 | E42: =calc_Charts!E20 -> 531 | F42: =calc_Charts!F20 -> 548 | G42: =calc_Charts!G20 -> 558 | H42: =calc_Charts!H20 -> 575 | I42: =calc_Charts!I20 -> 558 | J42: =calc_Charts!J20 -> 575 | ... AA42: =calc_Charts!AA20 -> #N/A
B43: Propane CIF ARA | C43: =calc_Charts!C91 -> 489 | D43: =calc_Charts!D91 -> 488 | E43: =calc_Charts!E91 -> 497 | F43: =calc_Charts!F91 -> 509 | G43: =calc_Charts!G91 -> 521 | H43: =calc_Charts!H91 -> 553 | I43: =calc_Charts!I91 -> 511 | J43: =calc_Charts!J91 -> 551 | ... AA43: =calc_Charts!AA91 -> #N/A
B44: Butane CIF ARA | C44: =calc_Charts!C96 -> 449 | D44: =calc_Charts!D96 -> 506 | E44: =calc_Charts!E96 -> 491 | F44: =calc_Charts!F96 -> 504 | G44: =calc_Charts!G96 -> 511 | H44: =calc_Charts!H96 -> 527 | I44: =calc_Charts!I96 -> 485 | J44: =calc_Charts!J96 -> 507 | ... AA44: =calc_Charts!AA96 -> #N/A
B47: GPPS FD NWE | C47: =calc_Charts!C81 -> #N/A | D47: =calc_Charts!D81 -> #N/A | E47: =calc_Charts!E81 -> #N/A | F47: =calc_Charts!F81 -> #N/A | G47: =calc_Charts!G81 -> #N/A | H47: =calc_Charts!H81 -> #N/A | I47: =calc_Charts!I81 -> #N/A | J47: =calc_Charts!J81 -> #N/A | ... AA47: =calc_Charts!AA81 -> #N/A
B48: Styrene FOB ARA | C48: =C32 -> 779.06977 | D48: =D32 -> 810.46512 | E48: =E32 -> 819.76744 | F48: =F32 -> 873.80952 | G48: =G32 -> 864.70588 | H48: =H32 -> 895.2381 | I48: =I32 -> 915.29412 | J48: =J32 -> 988.23529 | ... AA48: =AA32 -> #N/A
B49: Benzene CIF Rotterdam | C49: =C33 -> 745 | D49: =D33 -> 770 | E49: =E33 -> 785 | F49: =F33 -> 820 | G49: =G33 -> 825 | H49: =H33 -> 825 | I49: =I33 -> 825 | J49: =J33 -> 840 | ... AA49: =AA33 -> #N/A
B52: GPPS CFR China | C52: =calc_Charts!C91 -> 489 | D52: =calc_Charts!D91 -> 488 | E52: =calc_Charts!E91 -> 497 | F52: =calc_Charts!F91 -> 509 | G52: =calc_Charts!G91 -> 521 | H52: =calc_Charts!H91 -> 553 | I52: =calc_Charts!I91 -> 511 | J52: =calc_Charts!J91 -> 551 | ... AA52: =calc_Charts!AA91 -> #N/A
B53: Styrene CFR China | C53: =calc_Charts!C96 -> 449 | D53: =calc_Charts!D96 -> 506 | E53: =calc_Charts!E96 -> 491 | F53: =calc_Charts!F96 -> 504 | G53: =calc_Charts!G96 -> 511 | H53: =calc_Charts!H96 -> 527 | I53: =calc_Charts!I96 -> 485 | J53: =calc_Charts!J96 -> 507 | ... AA53: =calc_Charts!AA96 -> #N/A
